Workbook

Sheet Read Me
B1: Paytm Innovation Challenge 2026 · Round 2 Annexure · Paytm Chukta
B2: Kartik Raj · IIT Kanpur · Individual entry · Track B: Grow Paytm usage among merchants as UPI payers
B4: What this is | C4: Supporting evidence for KartikRaj_R2.pdf. Round 1 evidence (50 VOCs) is copied in "R1 VOC" and remains in KartikRaj_VOC.xlsx.
B5: How Round 2 was run | C5: In-person interviews in Kanpur on 8 Oct 2026: 21 shop owners (screened: decides supplier payments, receives on Paytm, paid a supplier in the last 7 days) and 4 distributors. Concept shown on a board; all answers given verbally and recorded as voice notes, then logged here.
B6: What the evidence is | C6: Stated answers and stated commitments. No prototype walkthroughs or live payments were run in Round 2: usability and real payment behaviour are tested in week 1–2 of the 90-day pilot.
B7: Verbatims | C7: Column N is transcribed from voice notes. Where several owners made the same point, it is logged under one common wording.
B8: R2 Validation Log | C8: One row per shop owner. Ladder columns Q–T record what the owner SAID they would do, not observed behaviour.
B9: Distributor Log | C9: One row per distributor / wholesaler (software used, payment mix, ledger offer, pilot interest).
B10: R2 Validation Dashboard | C10: Every number is a formula on the two logs; these are the figures on slides 1, 6 and 7.
B11: Business Model | C11: Opportunity sizing, Year 1–3 GMV, segment share, revenue, cost, cost per active shop and per ₹1,000 GMV. Blue = input (each with source); black = formula.
B12: Sensitivity | C12: One-at-a-time tornado on the Year 3 drivers (slide 15).
B13: Pilot Design | C13: 90-day cluster-randomised Kanpur pilot: cohort, targets, decision rules, power calculation (slide 12).
B14: Journey · Build · Risks | C14: Before/after journey, build effort and dependencies, risk register (slides 8, 10, 15).
B15: Sources | C15: Every external number with its link.
B16: Colour legend | C16: Yellow fill = field data · Blue text = hard-coded input / assumption · Black = formula · Green = link to another sheet.

Sheet R2 Validation Log
A1: R2 Validation Log · one row per shop owner (screener + concept + stated ladder)
A2: Interviews 8 Oct 2026, Kanpur. Answers given verbally (voice notes). Anonymised: area + shop type only.
A5: Respondent ID | B5: Date | C5: Area | D5: Category | E5: Role | F5: Receives customer payments on | G5: R1 respondent re-contacted? | H5: Last supplier payment ₹ | I5: App used for it | J5: Paid from which phone | K5: Minutes taken (last real payment) | L5: A1 Usefulness 1–5 | M5: A2 Move next bill to Chukta? | N5: A3 Main objection (from voice note) | O5: Objection code | P5: Bills they receive (stated) | Q5: L1 Would share a real bill to be read (said) | R5: L2 Would add suppliers + 9 pm reminder (said) | S5: L3 Would pay next supplier bill via Paytm (said) | T5: L4 Wants to join 90-day pilot (said) | U5: Wants Chukta on personal phone | V5: Notes
A6: R2-01 | B6: 46303 | C6: Kakadeo | D6: Kirana / grocery | E6: Owner | F6: Paytm QR only | G6: Yes | H6: 4369 | I6: PhonePe | J6: Owner personal phone | K6: 2 | L6: 5 | M6: Yes | N6: Idea acha hai 9 baje wala reminder badhiya hai. | O6: None | P6: Paper / photo / WhatsApp | Q6: Yes | R6: No | S6: No | T6: No | U6: Yes
A7: R2-02 | B7: 46303 | C7: Kalyanpur | D7: Kirana / grocery | E7: Owner | F7: Paytm Soundbox | G7: Yes | H7: 36592 | I7: PhonePe | J7: Owner personal phone | K7: 4 | L7: 4 | M7: Maybe | N7: Idea acha hai 9 baje wala reminder badhiya hai. | O7: None | P7: Paper / photo / WhatsApp | Q7: Yes | R7: Yes | S7: No | T7: No | U7: Yes
A8: R2-03 | B8: 46303 | C8: Kalyanpur | D8: Kirana / grocery | E8: Family member / partner | F8: Paytm Soundbox | G8: Yes | H8: 31086 | I8: PhonePe | J8: Owner personal phone | K8: 3 | L8: 5 | M8: Maybe | N8: Paisa agar fas gaya toh kon jimmedar hoga? | O8: Trust / fraud worry | P8: e-Invoice QR | Q8: Yes | R8: Yes | S8: No bill due | T8: Yes | U8: Yes
A9: R2-04 | B9: 46303 | C9: MT Section | D9: Kirana / grocery | E9: Family member / partner | F9: Paytm + other QR | G9: Yes | H9: 32247 | I9: PhonePe | J9: Owner personal phone | K9: 3 | L9: 4 | M9: Yes | N9: Salesman apna hi QR deta hai distributor bolega tabhi karunga. | O9: Distributor must agree | P9: Paper / photo / WhatsApp | Q9: Yes | R9: Yes | S9: No | T9: Yes | U9: Yes
A10: R2-05 | B10: 46303 | C10: Swaroop Nagar | D10: Kirana / grocery | E10: Owner | F10: Paytm Soundbox | G10: Yes | H10: 28080 | I10: PhonePe | J10: Owner personal phone | K10: 4 | L10: 5 | M10: Maybe | N10: Pehle credit mile tab ye use karne ka faida. | O10: Wants credit first | P10: e-Invoice QR | Q10: Yes | R10: Yes | S10: Yes | T10: Yes | U10: Yes
A11: R2-06 | B11: 46303 | C11: Kakadeo | D11: Kirana / grocery | E11: Owner | F11: Paytm Soundbox | G11: Yes | H11: 32306 | I11: PhonePe | J11: Owner personal phone | K11: 5 | L11: 5 | M11: Yes | N11: GPay ki aadat pad gayi hai fast hota hai. | O11: Prefer current app | P11: e-Invoice QR | Q11: Yes | R11: No | S11: Yes | T11: Yes | U11: Yes
A12: R2-07 | B12: 46303 | C12: IITK Shopping Complex | D12: Kirana / grocery | E12: Owner | F12: Paytm QR only | G12: Yes | H12: 28965 | I12: PhonePe | J12: Owner personal phone | K12: 4 | L12: 4 | M12: Maybe | N12: Salesman apna hi QR deta hai distributor bolega tabhi karunga. | O12: Distributor must agree | P12: Paper / photo / WhatsApp | Q12: Yes | R12: No | S12: Already paid | T12: Yes | U12: Yes
A13: R2-08 | B13: 46303 | C13: MT Section | D13: Kirana / grocery | E13: Family member / partner | F13: Paytm Soundbox | G13: Yes | H13: 43851 | I13: PhonePe | J13: Owner personal phone | K13: 5 | L13: 4 | M13: Maybe | N13: GPay ki aadat pad gayi hai fast hota hai. | O13: Prefer current app | P13: Paper / photo / WhatsApp | Q13: Yes | R13: No | S13: No bill due | T13: No | U13: Yes
A14: R2-09 | B14: 46303 | C14: Kalyanpur | D14: General / FMCG store | E14: Owner | F14: Paytm + other QR | G14: Yes | H14: 40461 | I14: PhonePe | J14: Owner personal phone | K14: 5 | L14: 5 | M14: Maybe | N14: Idea acha hai 9 baje wala reminder badhiya hai. | O14: None | P14: Paper / photo / WhatsApp | Q14: Yes | R14: No | S14: No bill due | T14: Yes | U14: Yes
A15: R2-10 | B15: 46303 | C15: Swaroop Nagar | D15: General / FMCG store | E15: Family member / partner | F15: Paytm Soundbox | G15: Yes | H15: 19902 | I15: PhonePe | J15: Owner personal phone | K15: 5 | L15: 4 | M15: Maybe | N15: Mera PhonePe theek chal raha hai naya aadat kyu daalun. | O15: Prefer current app | P15: Paper / photo / WhatsApp | Q15: Yes | R15: No | S15: Yes | T15: Yes | U15: Yes
A16: R2-11 | B16: 46303 | C16: Kalyanpur | D16: Pharmacy / chemist | E16: Owner | F16: Paytm QR only | G16: No | H16: 42691 | I16: Google Pay | J16: Owner personal phone | K16: 5 | L16: 5 | M16: Yes | N16: Paisa agar fas gaya toh kon jimmedar hoga? | O16: Trust / fraud worry | P16: e-Invoice QR | Q16: Yes | R16: Yes | S16: Yes | T16: Yes | U16: Yes
A17: R2-12 | B17: 46303 | C17: Swaroop Nagar | D17: Pharmacy / chemist | E17: Family member / partner | F17: Paytm Soundbox | G17: No | H17: 26742 | I17: Google Pay | J17: Owner personal phone | K17: 3 | L17: 4 | M17: Yes | N17: Pehle credit mile tab ye use karne ka faida. | O17: Wants credit first | P17: e-Invoice QR | Q17: Yes | R17: Yes | S17: Already paid | T17: Yes | U17: Yes
... A26: R2-21 | B26: 46303 | C26: Nankari | D26: Hardware / paint / sanitary | E26: Owner | F26: Paytm Soundbox | G26: No | H26: 21981 | I26: Cash | J26: Owner personal phone | K26: 2 | L26: 5 | M26: Maybe | N26: Naya system sikhna padega time nahi hai. | O26: Too many steps | P26: Paper / photo / WhatsApp | Q26: Yes | R26: No | S26: No | T26: No | U26: Yes

Sheet Distributor Log
A1: Distributor Log · supply-side interviews (the actor whose salesman shows the QR)
A2: Interviews 8 Oct 2026, Kanpur. Owner or accounts head; answers given verbally.
A5: Distributor ID | B5: Date | C5: Market / area | D5: Category | E5: Retailers served | F5: Monthly sales ₹ (approx) | G5: Retailer credit days | H5: Billing software | I5: Issues e-invoices (IRN)? | J5: Share of collections: cash % | K5: Share: UPI QR % | L5: Share: bank transfer % | M5: Concern about 0.4% MDR? | N5: Offered to share 4-week payment ledger? | O5: Agreed to join pilot (verbal, non-binding)? | P5: Key quote (from voice note) | Q5: Notes
A6: D-01 | B6: 46303 | C6: Nayaganj | D6: FMCG | E6: 250 | F6: 1.5 Cr | G6: 7 | H6: Marg | I6: Not sure | J6: 20 | K6: 60 | L6: 20 | M6: Yes (concerned) | N6: Yes | O6: Yes | P6: Agar collection apne aap track ho jaye bina salesman ke, toh badhiya hai.
A7: D-02 | B7: 46303 | C7: Swaroop Nagar | D7: Pharma | E7: 150 | F7: 2 Cr | G7: 14 | H7: Tally | I7: Yes | J7: 10 | K7: 40 | L7: 50 | M7: No / not aware | N7: Maybe later | O7: Yes | P7: Medical dukaandar bahut bill guma dete hain, app mein rahe toh payment jaldi aayega.
A8: D-03 | B8: 46303 | C8: Generalganj | D8: Mixed | E8: 400 | F8: 80 L | G8: 0 | H8: Busy | I8: Not sure | J8: 40 | K8: 50 | L8: 10 | M8: No / not aware | N8: Yes | O8: Maybe later | P8: Abhi mera system set hai, pehle 10 dukaandar se test karwao phir main sochunga.
A9: D-04 | B9: 46303 | C9: Birhana Road | D9: Hardware | E9: 100 | F9: 50 L | G9: 30 | H9: None / paper | I9: No | J9: 30 | K9: 20 | L9: 50 | M9: Yes (concerned) | N9: No | O9: No | P9: Hardware mein amount bada hota hai, log NEFT hi karte hain, QR nahi chalega. | Q9: Only accepts NEFT for large orders

Sheet R2 Validation Dashboard
A1: R2 Validation Dashboard · all formulas on the two logs
A2: Stated answers, 8 Oct 2026. The "deck key" column matches validation.json used to build the PDF.
A4: Metric | B4: Value | C4: Base (n) | D4: deck key | E4: How it is computed | F4: % of base
A5: Shop owners interviewed | B5: =COUNTA('R2 Validation Log'!$A$6:$A$105) -> 21 | D5: merchants_tested | E5: Rows with a Respondent ID | F5: =IF(OR(C5="",C5=0),"",B5/C5)
A6: Distributors interviewed | B6: =COUNTA('Distributor Log'!$A$6:$A$25) -> 4 | D6: distributors_tested | E6: Distributor Log rows | F6: =IF(OR(C6="",C6=0),"",B6/C6)
A7: Concept test respondents (n) | B7: =COUNT('R2 Validation Log'!$L$6:$L$105) -> 21 | D7: concept_n | E7: A1 answered | F7: =IF(OR(C7="",C7=0),"",B7/C7)
A8: Rated usefulness 4 or 5 | B8: =COUNTIF('R2 Validation Log'!$L$6:$L$105,">=4") -> 20 | C8: =B7 -> 21 | D8: concept_top2 | E8: A1 | F8: =IF(OR(C8="",C8=0),"",B8/C8) -> 0.95238095
A9: Would move next bill to Chukta: Yes | B9: =COUNTIF('R2 Validation Log'!$M$6:$M$105,"Yes") -> 8 | C9: =B7 -> 21 | D9: a2_yes | E9: A2 forced choice vs current app | F9: =IF(OR(C9="",C9=0),"",B9/C9) -> 0.38095238
A10: Would move next bill to Chukta: Maybe | B10: =COUNTIF('R2 Validation Log'!$M$6:$M$105,"Maybe") -> 13 | C10: =B7 -> 21 | D10: a2_maybe | E10: A2 | F10: =IF(OR(C10="",C10=0),"",B10/C10) -> 0.61904762
A11: Ladder respondents (n) | B11: =COUNTA('R2 Validation Log'!$Q$6:$Q$105) -> 21 | D11: walk_n | E11: Answered the ladder questions | F11: =IF(OR(C11="",C11=0),"",B11/C11)
A12: Median minutes for their last real supplier payment | B12: =IF(COUNT('R2 Validation Log'!$K$6:$K$105)=0,"–",MEDIAN('R2 Validation Log'!$K$6:$K$105)) -> 4 | D12: today_min | E12: Screener S3 | F12: =IF(OR(C12="",C12=0),"",B12/C12)
A13: L1 Said they would share a real bill | B13: =COUNTIF('R2 Validation Log'!$Q$6:$Q$105,"Yes") -> 21 | C13: =B11 -> 21 | D13: l1_bill | E13: Stated | F13: =IF(OR(C13="",C13=0),"",B13/C13) -> 1
A14: L2 Said they would add suppliers + reminder | B14: =COUNTIF('R2 Validation Log'!$R$6:$R$105,"Yes") -> 8 | C14: =B11 -> 21 | D14: l2_reminder | E14: Stated | F14: =IF(OR(C14="",C14=0),"",B14/C14) -> 0.38095238
A15: L3 Said they would pay next supplier bill via Paytm | B15: =COUNTIF('R2 Validation Log'!$S$6:$S$105,"Yes") -> 7 | C15: =B11 -> 21 | D15: l3_paid | E15: Stated, not observed | F15: =IF(OR(C15="",C15=0),"",B15/C15) -> 0.33333333
A16: L4 Want to join the 90-day pilot | B16: =COUNTIF('R2 Validation Log'!$T$6:$T$105,"Yes") -> 13 | C16: =B11 -> 21 | D16: l4_pilot | E16: Stated | F16: =IF(OR(C16="",C16=0),"",B16/C16) -> 0.61904762
A17: Want Chukta on personal phone | B17: =COUNTIF('R2 Validation Log'!$U$6:$U$105,"Yes") -> 21 | C17: =B11 -> 21 | D17: personal_phone | F17: =IF(OR(C17="",C17=0),"",B17/C17) -> 1
A18: Shops that receive supplier bills (stated) | B18: =COUNTA('R2 Validation Log'!$P$6:$P$105)-COUNTIF('R2 Validation Log'!$P$6:$P$105,"No bills") -> 21 | D18: bills_seen | F18: =IF(OR(C18="",C18=0),"",B18/C18)
A19: …whose bills carry an e-invoice QR (stated) | B19: =COUNTIF('R2 Validation Log'!$P$6:$P$105,"e-Invoice QR") -> 7 | C19: =B18 -> 21 | D19: einv_bills | F19: =IF(OR(C19="",C19=0),"",B19/C19) -> 0.33333333
A20: Distributors who agreed to join the pilot | B20: =COUNTIF('Distributor Log'!$O$6:$O$25,"Yes") -> 2 | C20: =B6 -> 4 | D20: d_loi | E20: Verbal, non-binding | F20: =IF(OR(C20="",C20=0),"",B20/C20) -> 0.5
A21: Distributors who offered a 4-week ledger | B21: =COUNTIF('Distributor Log'!$N$6:$N$25,"Yes") -> 2 | C21: =B6 -> 4 | D21: d_ledger | F21: =IF(OR(C21="",C21=0),"",B21/C21) -> 0.5
A22: Distributors on Tally / Marg / Busy | B22: =COUNTIF('Distributor Log'!$H$6:$H$25,"Tally")+COUNTIF('Distributor Log'!$H$6:$H$25,"Marg")+COUNTIF('Distributor Log'!$H$6:$H$25,"Busy") -> 3 | C22: =B6 -> 4 | D22: d_erp | F22: =IF(OR(C22="",C22=0),"",B22/C22) -> 0.75
A24: Quota check (slide 6) | B24: Interviewed | C24: Quota | D24: deck key | G24: L3 said yes (slide 7) | H24: deck key
A25: Kirana / general FMCG | B25: =COUNTIF('R2 Validation Log'!$D$6:$D$105,"Kirana / grocery")+COUNTIF('R2 Validation Log'!$D$6:$D$105,"General / FMCG store") -> 10 | C25: 10 | D25: q_kirana | G25: =COUNTIFS('R2 Validation Log'!$D$6:$D$105,"Kirana / grocery",'R2 Validation Log'!$S$6:$S$105,"Yes")+COUNTIFS('R2 Validation Log'!$D$6:$D$105,"General / FMCG store",'R2 Validation Log'!$S$6:$S$105,"Yes") -> 3 | H25: l3_kirana
A26: Chemist / pharmacy | B26: =COUNTIF('R2 Validation Log'!$D$6:$D$105,"Pharmacy / chemist") -> 4 | C26: 5 | D26: q_pharma | G26: =COUNTIFS('R2 Validation Log'!$D$6:$D$105,"Pharmacy / chemist",'R2 Validation Log'!$S$6:$S$105,"Yes") -> 3 | H26: l3_pharma
A27: Canteen / dairy / bakery | B27: =COUNTIF('R2 Validation Log'!$D$6:$D$105,"Restaurant / dhaba / canteen")+COUNTIF('R2 Validation Log'!$D$6:$D$105,"Dairy / bakery / sweets") -> 4 | C27: 5 | D27: q_canteen | G27: =COUNTIFS('R2 Validation Log'!$D$6:$D$105,"Restaurant / dhaba / canteen",'R2 Validation Log'!$S$6:$S$105,"Yes")+COUNTIFS('R2 Validation Log'!$D$6:$D$105,"Dairy / bakery / sweets",'R2 Validation Log'!$S$6:$S$105,"Yes") -> 1 | H27: l3_canteen
A28: Hardware / electronics / other | B28: =B5-B25-B26-B27 -> 3 | C28: 5 | D28: q_other | G28: =B15-G25-G26-G27 -> 0 | H28: l3_other
A30: Pass bars (slide 7) | B30: Result | C30: Bar | D30: Verdict
A31: H1 Desirability (stated): share saying they would pay next bill via Paytm | B31: =F15 -> 0.33333333 | C31: 0.3 | D31: =IF(B31="","–",IF(B31>=C31,"PASS","BELOW BAR")) -> PASS
A32: H2 Channel: distributors agreeing to join the pilot (count) | B32: =B20 -> 2 | C32: 2 | D32: =IF(B32="","–",IF(B32>=C32,"PASS","BELOW BAR")) -> PASS
A33: H3 Feasibility: bills captured without typing | B33: Not run in R2 | C33: 70% | D33: Pilot week 1–2
A34: Usability: tasks completed unaided on the prototype | B34: Not run in R2 | C34: 70% | D34: Pilot week 1–2
A36: Objection codes (for "We heard → our response") | B36: Count
A37: Distributor must agree | B37: =COUNTIF('R2 Validation Log'!$O$6:$O$105,"Distributor must agree") -> 5
A38: Trust / fraud worry | B38: =COUNTIF('R2 Validation Log'!$O$6:$O$105,"Trust / fraud worry") -> 2
A39: Prefer current app | B39: =COUNTIF('R2 Validation Log'!$O$6:$O$105,"Prefer current app") -> 5
A40: Too many steps | B40: =COUNTIF('R2 Validation Log'!$O$6:$O$105,"Too many steps") -> 2
A41: Phone / account mismatch | B41: =COUNTIF('R2 Validation Log'!$O$6:$O$105,"Phone / account mismatch") -> 1
A42: Bills are paper only | B42: =COUNTIF('R2 Validation Log'!$O$6:$O$105,"Bills are paper only") -> 1
A43: Wants credit first | B43: =COUNTIF('R2 Validation Log'!$O$6:$O$105,"Wants credit first") -> 2
A44: Data privacy | B44: =COUNTIF('R2 Validation Log'!$O$6:$O$105,"Data privacy") -> 0
...

Sheet Business Model
A1: Business Model · Paytm Chukta (national roll-out)
A2: Blue = input with source. Black = formula. ₹ Cr unless stated. Same inputs generate the deck (slides 13–15, A1).
A4: A. Inputs (single value) | B4: Value | F4: Source / reasoning
A5: Paytm device merchants | B5: 15700000 | F5: Paytm Q1 FY27 results, Jul 2026 (1.57 crore device merchants)
A6: Share buying stock from suppliers | B6: 0.45 | F6: Assumption: retail-heavy Soundbox base; excludes services
A7: …of which pay suppliers over UPI monthly | B7: 0.6 | F7: Conservative; Kanpur R1 VOC: 48 of 50
A8: Supplier UPI per shop per month (₹) | B8: 60000 | F8: ₹3 L sales × ~80% stock × ~25% UPI; Kanpur R1 average ₹1.09 L
A9: Paytm share of this UPI today | B9: 0.08 | F9: Paytm national app share 8.1% (Aug 2026); Kanpur R1 sample 0%
A10: Supplier payments per shop per month (all apps) | B10: 10 | F10: R1 VOC use-case frequencies
A11: MDR-eligible share of Chukta GMV (P2M > ₹2,000) | B11: 0.5 | F11: Rest: bank-a/c rail, P2PM-exempt small suppliers, tickets ≤ ₹2,000
A12: Payer-app (TPAP) share of MDR | B12: 0.0008 | F12: NPCI 15 Sep 2026: 0.4% MDR, 20% to UPI app
A13: Share of supplier QRs acquired by Paytm | B13: 0.3 | F13: Assumption: Chukta Collect onboards distributors to Paytm QR
A14: Acquirer share of MDR | B14: 0.0012 | F14: NPCI 15 Sep 2026: 30% of 0.4% to acquirer
A15: Credit drawn per credit user per month (₹) | B15: 20000 | F15: Assumption: ~1/3 of monthly supplier UPI
A16: Paytm distribution take on credit | B16: 0.015 | F16: Assumption; depends on lender contracts
... A23: National UPI value per month (₹ Cr) | B23: 2990000 | F23: NPCI, Aug 2026: ₹29.9 lakh crore
A25: B. Inputs by year | B25: Year 1 | C25: Year 2 | D25: Year 3 | F25: Source / reasoning
A26: Adoption: % of target shops active | B26: 0.08 | C26: 0.2 | D26: 0.35 | F26: Cut from R1 (15/30/45%) after stress test; pilot activation bar 40% of reachable
A27: Paytm share of an adopter's supplier UPI | B27: 0.5 | C27: 0.6 | D27: 0.7 | F27: Remainder: cash-only and non-Chukta suppliers
A28: Credit users among adopters | B28: 0.1 | C28: 0.15 | D28: 0.2 | F28: Credit launches after payment habit; lender-approved only
A30: C. Segment | B30: Value | F30: Formula
A31: Target shops (device × stock × UPI) | B31: =$B$5*$B$6*$B$7 -> 4239000 | F31: Slide 13 funnel
A32: Pool: supplier UPI per month (₹ Cr) | B32: =B31*$B$8/10000000 -> 25434
A33: Pool per year (₹ Cr) | B33: =B32*12 -> 305208
A34: Paytm GMV from pool today (₹ Cr / month) | B34: =B32*$B$9 -> 2034.72
A36: D. Year-by-year | B36: Year 1 | C36: Year 2 | D36: Year 3 | E36: 3-yr total | F36: Formula note
A37: Active Chukta shops | B37: =$B$31*B26 -> 339120 | C37: =$B$31*C26 -> 847800 | D37: =$B$31*D26 -> 1483650 | E37: =SUM(B37:D37) -> 2670570 | F37: Target × adoption
A38: Share-of-wallet uplift (pp) | B38: =B27-$B$9 -> 0.42 | C38: =C27-$B$9 -> 0.52 | D38: =D27-$B$9 -> 0.62 | F38: Adopter share − today
A39: Incremental GMV per month (₹ Cr) | B39: =B37*$B$8*B38/10000000 -> 854.5824 | C39: =C37*$B$8*C38/10000000 -> 2645.136 | D39: =D37*$B$8*D38/10000000 -> 5519.178
A40: Incremental GMV per year (₹ Cr) | B40: =B39*12 -> 10254.989 | C40: =C39*12 -> 31741.632 | D40: =D39*12 -> 66230.136 | E40: =SUM(B40:D40) -> 108226.76 | F40: Main volume number
A41: Incremental UPI transactions per month | B41: =B37*$B$10*B38 -> 1424304 | C41: =C37*$B$10*C38 -> 4408560 | D41: =D37*$B$10*D38 -> 9198630
A42: Paytm share of segment supplier UPI | B42: =$B$9+B39/$B$32 -> 0.1136 | C42: =$B$9+C39/$B$32 -> 0.184 | D42: =$B$9+D39/$B$32 -> 0.297 | F42: MAIN METRIC (slide 13)
A43: Added to Paytm share of all UPI value (pp) | B43: =B39/$B$23*100 -> 0.028581351 | C43: =C39/$B$23*100 -> 0.088466087 | D43: =D39/$B$23*100 -> 0.18458789
A44: Revenue: payer-app MDR | B44: =B40*$B$11*$B$12 -> 4.1019955 | C44: =C40*$B$11*$B$12 -> 12.696653 | D44: =D40*$B$11*$B$12 -> 26.492054 | E44: =SUM(B44:D44) -> 43.290703
A45: Revenue: acquirer MDR | B45: =B40*$B$11*$B$13*$B$14 -> 1.845898 | C45: =C40*$B$11*$B$13*$B$14 -> 5.7134938 | D45: =D40*$B$11*$B$13*$B$14 -> 11.921424 | E45: =SUM(B45:D45) -> 19.480816
A46: Credit users | B46: =B37*B28 -> 33912 | C46: =C37*C28 -> 127170 | D46: =D37*D28 -> 296730
A47: Credit disbursed (₹ Cr / yr) | B47: =B46*$B$15*12/10000000 -> 813.888 | C47: =C46*$B$15*12/10000000 -> 3052.08 | D47: =D46*$B$15*12/10000000 -> 7121.52 | E47: =SUM(B47:D47) -> 10987.488
A48: Revenue: credit distribution | B48: =B47*$B$16 -> 12.20832 | C48: =C47*$B$16 -> 45.7812 | D48: =D47*$B$16 -> 106.8228 | E48: =SUM(B48:D48) -> 164.81232
A49: Total revenue | B49: =B44+B45+B48 -> 18.156214 | C49: =C44+C45+C48 -> 64.191347 | D49: =D44+D45+D48 -> 145.23628 | E49: =SUM(B49:D49) -> 227.58384
A50: New active shops in year | B50: =B37 -> 339120 | C50: =C37-B37 -> 508680 | D50: =D37-C37 -> 635850 | E50: =SUM(B50:D50) -> 1483650
...

Sheet Sensitivity
A1: Sensitivity · Year 3, one assumption at a time (slide 15)
A2: Low / high values are blue inputs. Other inputs are linked (green) to Business Model.
A4: Base Year 3 incremental GMV (₹ Cr / yr) | B4: ='Business Model'!D40 -> 66230.136
A5: Base Year 3 revenue (₹ Cr / yr) | B5: ='Business Model'!D49 -> 145.23628
A7: Driver | B7: Low | C7: High | D7: GMV at low | E7: GMV at high | F7: Revenue at low | G7: Revenue at high
A8: Year 3 adoption of target shops | B8: 0.2 | C8: 0.5 | D8: ='Business Model'!$B$31*B8*'Business Model'!$B$8*('Business Model'!$D$27-'Business Model'!$B$9)*12/10000000 -> 37845.792 | E8: ='Business Model'!$B$31*C8*'Business Model'!$B$8*('Business Model'!$D$27-'Business Model'!$B$9)*12/10000000 -> 94614.48 | F8: ='Business Model'!$B$31*B8*'Business Model'!$B$8*('Business Model'!$D$27-'Business Model'!$B$9)*12/10000000*'Business Model'!$B$11*('Business Model'!$B$12+'Business Model'!$B$13*'Business Model'!$B$14)+'Business Model'!$B$31*B8*'Business Model'!$D$28*'Business Model'!$B$15*12/10000000*'Business Model'!$B$16 -> 82.992159 | G8: ='Business Model'!$B$31*C8*'Business Model'!$B$8*('Business Model'!$D$27-'Business Model'!$B$9)*12/10000000*'Business Model'!$B$11*('Business Model'!$B$12+'Business Model'!$B$13*'Business Model'!$B$14)+'Business Model'!$B$31*C8*'Business Model'!$D$28*'Business Model'!$B$15*12/10000000*'Business Model'!$B$16 -> 207.4804
A9: Supplier UPI per shop per month (₹) | B9: 40000 | C9: 80000 | D9: ='Business Model'!$B$31*'Business Model'!$D$26*B9*('Business Model'!$D$27-'Business Model'!$B$9)*12/10000000 -> 44153.424 | E9: ='Business Model'!$B$31*'Business Model'!$D$26*C9*('Business Model'!$D$27-'Business Model'!$B$9)*12/10000000 -> 88306.848 | F9: ='Business Model'!$B$31*'Business Model'!$D$26*B9*('Business Model'!$D$27-'Business Model'!$B$9)*12/10000000*'Business Model'!$B$11*('Business Model'!$B$12+'Business Model'!$B$13*'Business Model'!$B$14)+'Business Model'!$B$31*'Business Model'!$D$26*'Business Model'!$D$28*'Business Model'!$B$15*12/10000000*'Business Model'!$B$16 -> 132.43179 | G9: ='Business Model'!$B$31*'Business Model'!$D$26*C9*('Business Model'!$D$27-'Business Model'!$B$9)*12/10000000*'Business Model'!$B$11*('Business Model'!$B$12+'Business Model'!$B$13*'Business Model'!$B$14)+'Business Model'!$B$31*'Business Model'!$D$26*'Business Model'!$D$28*'Business Model'!$B$15*12/10000000*'Business Model'!$B$16 -> 158.04077
A10: Paytm share of an adopter's supplier UPI | B10: 0.55 | C10: 0.85 | D10: ='Business Model'!$B$31*'Business Model'!$D$26*'Business Model'!$B$8*(B10-'Business Model'!$B$9)*12/10000000 -> 50206.716 | E10: ='Business Model'!$B$31*'Business Model'!$D$26*'Business Model'!$B$8*(C10-'Business Model'!$B$9)*12/10000000 -> 82253.556 | F10: ='Business Model'!$B$31*'Business Model'!$D$26*'Business Model'!$B$8*(B10-'Business Model'!$B$9)*12/10000000*'Business Model'!$B$11*('Business Model'!$B$12+'Business Model'!$B$13*'Business Model'!$B$14)+'Business Model'!$B$31*'Business Model'!$D$26*'Business Model'!$D$28*'Business Model'!$B$15*12/10000000*'Business Model'!$B$16 -> 135.9427 | G10: ='Business Model'!$B$31*'Business Model'!$D$26*'Business Model'!$B$8*(C10-'Business Model'!$B$9)*12/10000000*'Business Model'!$B$11*('Business Model'!$B$12+'Business Model'!$B$13*'Business Model'!$B$14)+'Business Model'!$B$31*'Business Model'!$D$26*'Business Model'!$D$28*'Business Model'!$B$15*12/10000000*'Business Model'!$B$16 -> 154.52986
A11: MDR-eligible share of Chukta GMV | B11: 0.2 | C11: 0.7 | D11: ='Business Model'!$B$31*'Business Model'!$D$26*'Business Model'!$B$8*('Business Model'!$D$27-'Business Model'!$B$9)*12/10000000 -> 66230.136 | E11: ='Business Model'!$B$31*'Business Model'!$D$26*'Business Model'!$B$8*('Business Model'!$D$27-'Business Model'!$B$9)*12/10000000 -> 66230.136 | F11: ='Business Model'!$B$31*'Business Model'!$D$26*'Business Model'!$B$8*('Business Model'!$D$27-'Business Model'!$B$9)*12/10000000*B11*('Business Model'!$B$12+'Business Model'!$B$13*'Business Model'!$B$14)+'Business Model'!$B$31*'Business Model'!$D$26*'Business Model'!$D$28*'Business Model'!$B$15*12/10000000*'Business Model'!$B$16 -> 122.18819 | G11: ='Business Model'!$B$31*'Business Model'!$D$26*'Business Model'!$B$8*('Business Model'!$D$27-'Business Model'!$B$9)*12/10000000*C11*('Business Model'!$B$12+'Business Model'!$B$13*'Business Model'!$B$14)+'Business Model'!$B$31*'Business Model'!$D$26*'Business Model'!$D$28*'Business Model'!$B$15*12/10000000*'Business Model'!$B$16 -> 160.60167
A12: Credit users among adopters (Year 3) | B12: 0.1 | C12: 0.3 | D12: ='Business Model'!$B$31*'Business Model'!$D$26*'Business Model'!$B$8*('Business Model'!$D$27-'Business Model'!$B$9)*12/10000000 -> 66230.136 | E12: ='Business Model'!$B$31*'Business Model'!$D$26*'Business Model'!$B$8*('Business Model'!$D$27-'Business Model'!$B$9)*12/10000000 -> 66230.136 | F12: ='Business Model'!$B$31*'Business Model'!$D$26*'Business Model'!$B$8*('Business Model'!$D$27-'Business Model'!$B$9)*12/10000000*'Business Model'!$B$11*('Business Model'!$B$12+'Business Model'!$B$13*'Business Model'!$B$14)+'Business Model'!$B$31*'Business Model'!$D$26*B12*'Business Model'!$B$15*12/10000000*'Business Model'!$B$16 -> 91.824879 | G12: ='Business Model'!$B$31*'Business Model'!$D$26*'Business Model'!$B$8*('Business Model'!$D$27-'Business Model'!$B$9)*12/10000000*'Business Model'!$B$11*('Business Model'!$B$12+'Business Model'!$B$13*'Business Model'!$B$14)+'Business Model'!$B$31*'Business Model'!$D$26*C12*'Business Model'!$B$15*12/10000000*'Business Model'!$B$16 -> 198.64768
A14: Reading: adoption swings GMV most; credit uptake swings revenue most. GMV stays above ₹37,000 Cr in every tested case.

Sheet Pilot Design
A1: Pilot Design · 90-day cluster-randomised Kanpur pilot (slide 12)
A4: Element | B4: Value | C4: Detail
A5: Clusters (distributors) | B5: 20 | C5: FMCG + pharma, matched in pairs by size and category; one of each pair randomised to treatment
A6: Treatment / control | B6: 10 / 10 | C6: ~2,500 retailers per arm; ~1,500 Paytm device merchants per arm form the analysis cohort
A7: Baseline | B7: 4 weeks | C7: Distributor ledgers (invoice, amount, payment mode, app) + Paytm data; Account Aggregator consent on a 200-shop subsample
A8: Primary metric | B8: DiD | C8: Paytm share of supplier ₹ (treated − control, post − pre), standard errors clustered by distributor
A9: Credit | B9: Week 7+ | C9: Lender-approved sub-cohort only, analysed separately
A10: Incentive holdout | B10: Day 60 | C10: Distributor early-pay discount switched off for a random half of treated distributors
A11: Budget | B11: ₹10 L | C11: Field team 6 × 3 months ₹7.2 L · activation fees ₹0.5 L · onboarding ₹0.5 L · infra ₹0.3 L · comms ₹0.5 L · contingency ₹1 L
A13: Power calculation | B13: Value | C13: Formula / note
A14: Analysable shops per arm | B14: 1500 | C14: Input
A15: Clusters per arm | B15: 10 | C15: Input
A16: Intra-cluster correlation (ICC) | B16: 0.05 | C16: Assumed
A17: SD of shop-level Paytm share | B17: 0.35 | C17: Assumed (share is 0–1, bimodal)
A18: Shops per cluster | B18: =B14/B15 -> 150
A19: Design effect | B19: =1+(B18-1)*B16 -> 8.45 | C19: 1 + (m − 1) × ICC
A20: Effective shops per arm | B20: =B14/B19 -> 177.51479
A21: Minimum detectable effect (80% power, α = 0.05) | B21: =(1.96+0.84)*B17*SQRT(2/B20) -> 0.10402166 | C21: Target effect is +25 pp
A23: Day-90 target (treated Paytm device shops) | B23: Target | C23: Decision use
A24: Paytm share of supplier ₹: DiD vs control | B24: ≥ +25 pp | C24: Primary scale criterion
A25: Paytm share of supplier ₹ in treated shops | B25: ≥ 35%
A26: Activation: ≥ 1 bill paid in 14 days | B26: ≥ 40% | C26: STOP if < 15%
A27: Repeat: ≥ 3 bills in month 3 (of activated) | B27: ≥ 60% | C27: Scale criterion
A28: Invoices visible in Chukta | B28: ≥ 70%
A29: Retention after discount switched off at day 60 | B29: ≥ 85% | C29: Incentive-independence test
A30: Distributor days-to-collect | B30: −3 days
A31: Guardrails | B31: Failures < 1% · complaints < 2% · churn ≤ control | C31: Must hold to scale
A33: Decision rule | B33: Condition | C33: Next step
A34: SCALE | B34: DiD ≥ +25 pp and repeat ≥ 60% and guardrails met | C34: 10 high-Soundbox cities, 500 distributors, credit live
A35: ITERATE | B35: DiD +10 to +25 pp | C35: Fix weakest funnel step; extend 60 days
A36: STOP | B36: DiD < +10 pp or activation < 15% | C36: Keep only the Soundbox reminder

Sheet Journey · Build · Risks
A1: Before / after journey, build plan and risk register (slides 8, 10, 15)
A4: BEFORE step | B4: What happens | C4: Pain
A5: 1 Bill arrives | B5: Paper challan or WhatsApp PDF | C5: No due date tracked
A6: 2 Filed | B6: Drawer or chat | C6: Lost / forgotten
A7: 3 Collection | B7: Salesman visits or calls | C7: Owner on the spot
A8: 4 App | B8: PhonePe / GPay on personal phone | C8: Paytm never in hand
A9: 5 QR | B9: Scans whichever QR the salesman shows | C9: Salesman picks app
A10: 6 Amount | B10: Typed from challan or memory | C10: Typos, part-payments
A11: 7 Proof | B11: Screenshot on WhatsApp | C11: No invoice link
A12: 8 Matching | B12: Accountant matches by hand | C12: Disputes
A13: 9 Cash short | B13: Udhaar or delay | C13: Strains credit terms
A15: AFTER step | B15: What happens | C15: Paytm asset
A16: 1 Bill lands | B16: Distributor push / e-invoice QR / photo | C16: AI read, IRP QR verify
... A19: 4 Close | B19: Distributor auto-reconciled; purchase register | C19: Chukta Collect
A21: Component | B21: New / reuse | C21: Effort (S/M/L) | D21: In MVP? | E21: Note
A22: Bill inbox + ledger + due-date engine | B22: New | C22: M | D22: Yes | E22: Both apps, synced by merchant ID
A23: e-invoice QR read + IRP signature check | B23: New | C23: S | D23: Yes | E23: Public schema and key
A24: Photo / PDF bill read | B24: New (Paytm AI) | C24: M | D24: Yes | E24: Owner confirms
A25: Payee verification GSTIN ↔ VPA / a/c | B25: New | C25: S | D25: Yes | E25: Flags mismatches
A26: Soundbox "due tomorrow" line | B26: Reuse | C26: S | D26: Yes | E26: Script extension
A27: Invoice-tagged UPI pay | B27: Reuse | C27: S | D27: Yes | E27: Rail picked by supplier
A28: Chukta Collect web view | B28: New | C28: M | D28: Yes | E28: Read-only first
A29: Distributor push (API, Bharat Connect, Tally/Marg/Busy) | B29: New + partners | C29: L | D29: CSV in pilot
A30: Business credit line on UPI | B30: Partner | C30: L | D30: Week 7 sub-cohort | E30: P2M payees only
A31: GST purchase register export | B31: New | C31: S | D31: Phase 2
A33: Risk | B33: Mitigation | C33: Early signal | D33: L / I
A34: PhonePe / GPay copy the bill inbox | B34: Distributor lock-in first; ERP buttons; two-sided credit data | C34: Competitor launch; distributor churn | D34: H / M
A35: Competitor cashback war | B35: Don't match; workflow + records + credit | C35: Treated share falls > 5 pp | D35: M / M
A36: Distributors avoid MDR | B36: Rail-neutral: bank-a/c rail is MDR-free | C36: Rail mix in ledgers | D36: H / L
A37: Fake bill / QR-swap fraud | B37: GSTIN name match; e-invoice signature; 24 h cooling-off; push-only | C37: Name-mismatch rate | D37: M / H
A38: Credit losses | B38: Lender underwrites (RBI DLD 2025); small limits | C38: First-payment default | D38: M / M
A39: Habit doesn't form | B39: Nightly Soundbox ritual; STOP rule | C39: Repeat < 40% at D60 | D39: M / H
A40: Rule change (MDR rollback) | B40: MDR is a minority of revenue, 0% of GMV case | C40: NPCI circulars | D40: M / L
A41: Data privacy (DPDP) | B41: Consent per use; delete photos after reading | C41: Opt-out rate | D41: L / M

Sheet R1 VOC
A1: Round 1 VOC Collection (50 respondents) · values copied from KartikRaj_VOC.xlsx
A3: VOC ID | B3: Date | C3: Respondent type | D3: City / area | E3: Profile / category | F3: UPI apps used (you can mention multiple apps if used for different purposes/occasions) | G3: Primary UPI app used | H3: Why was it chosen? (exact words) | I3: When or why is Paytm used? Or not used if switched from Paytm? | J3: Need, barrier or motivation to switch (derived from the conversation, not a direct question - maybe a feature, campaign, perception etc.) | K3: Opportunity / idea | L3: Key quote | M3: Interview type | N3: Who decides supplier payments? | O3: Customers pay this shop mostly via | P3: Supplier payments made from | Q3: Est. monthly stock purchase (₹) | R3: Use case 1 | S3: UC1 payments / month | T3: UC1 typical amount (₹) | U3: UC1 paid with | V3: Use case 2 | W3: UC2 payments / month | X3: UC2 typical amount (₹) | Y3: UC2 paid with | Z3: Use case 3 | AA3: UC3 payments / month | AB3: UC3 typical amount (₹) | AC3: UC3 paid with | AD3: Main barrier to paying suppliers on Paytm (coded) | AE3: Knew Paytm can pay suppliers? | AF3: Reaction: 'supplier bills show up inside Paytm, pay in 1 tap' (1–5) | AG3: Would use 7-day pay-later for stock? | AH3: Any supplier asked for cash / bank transfer instead of QR recently? | AI3: CALC: Business UPI paid / month (₹) | AJ3: CALC: Paid via Paytm / month (₹) | AK3: CALC: Paytm share of business UPI | AL3: CALC: 'Leak' flag (receives on Paytm, pays suppliers mostly elsewhere)
A4: VOC-001 | B4: 46289 | C4: Merchant | D4: IITK Shopping Complex | E4: Kirana / grocery | F4: PhonePe for stock bills; Cash for staff salary | G4: PhonePe | H4: Paytm sirf aane ke liye hai, dena ho toh PhonePe khulta hai naturally. | I4: Customers pay on Paytm Soundbox; receiving only, no supplier payment goes through Paytm. Did not know Paytm can pay suppliers. | J4: Habit: other app is default | K4: Put the supplier bill inside Paytm + Soundbox reminder so Paytm becomes the default place to pay; keen on pay-later | L4: Paytm sirf aane ke liye hai, dena ho toh PhonePe khulta hai naturally. | M4: In-depth (15+ min) | N4: Owner | O4: Paytm Soundbox | P4: Owner's personal phone | Q4: 300000 | R4: Distributor / wholesaler (stock) | S4: 4 | T4: 40000 | U4: PhonePe | V4: Staff salary | W4: 1 | X4: 12000 | Y4: Cash | AD4: Habit: other app is default | AE4: No | AF4: 5 | AG4: Yes | AH4: Yes | AI4: 160000 | AJ4: 0 | AK4: 0 | AL4: 1
A5: VOC-002 | B5: 46289 | C5: Merchant | D5: IITK Shopping Complex | E5: Pharmacy / chemist | F5: Google Pay for stock bills; Bank transfer (NEFT/RTGS) for rent | G5: Google Pay | H5: Medical distributor apna GPay ka QR bhejta hai WhatsApp pe, wahi aasan hai. | I5: Customers pay on Paytm QR only; receiving only, no supplier payment goes through Paytm. Knew Paytm can pay suppliers but still uses other apps. | J5: Salesman shows his own QR | K5: Distributor-led onboarding: supplier's bill/QR lands in Chukta, salesman asks shop to pay there; keen on pay-later | L5: Medical distributor apna GPay ka QR bhejta hai WhatsApp pe, wahi aasan hai. | M5: In-depth (15+ min) | N5: Owner | O5: Paytm QR only | P5: Owner's personal phone | Q5: 500000 | R5: Distributor / wholesaler (stock) | S5: 8 | T5: 45000 | U5: Google Pay | V5: Shop rent | W5: 1 | X5: 15000 | Y5: Bank transfer (NEFT/RTGS) | AD5: Supplier shared another app's QR / asked | AE5: Yes | AF5: 4 | AG5: Yes | AH5: Not yet | AI5: 360000 | AJ5: 0 | AK5: 0 | AL5: 1
A6: VOC-003 | B6: 46289 | C6: Merchant | D6: Hall 1 Canteen | E6: Restaurant / dhaba / canteen | F6: Cash for daily perishables; PhonePe for daily perishables | G6: PhonePe | H6: Sabji wala cash mangta hai aur baki ke liye PhonePe use karte hain. | I6: Customers pay on Paytm Soundbox; receiving only, no supplier payment goes through Paytm. Did not know Paytm can pay suppliers. | J6: Short on cash when stock arrives | K6: 7-day pay-later at stock time; supplier still paid instantly | L6: Sabji wala cash mangta hai aur baki ke liye PhonePe use karte hain. | M6: In-depth (15+ min) | O6: Paytm Soundbox | P6: Mostly cash / cheque | Q6: 150000 | R6: Daily perishables (milk, bread, veg) | S6: 30 | T6: 2000 | U6: Cash | V6: Daily perishables (milk, bread, veg) | W6: 30 | X6: 1500 | Y6: PhonePe | AD6: Short on cash when stock arrives | AE6: No | AF6: 4 | AG6: Yes | AH6: Yes | AI6: 45000 | AJ6: 0 | AK6: 0 | AL6: 1
A7: VOC-004 | B7: 46289 | C7: Merchant | D7: Nankari | E7: Dairy / bakery / sweets | F7: PhonePe for stock bills; Google Pay for daily perishables | G7: PhonePe | H7: Dono kaam PhonePe se ho jate hain toh Paytm kyu rakhu. | I7: Customers pay on PhonePe Smartspeaker / QR; Paytm not used for receiving or paying suppliers. Did not know Paytm can pay suppliers. | J7: Habit: other app is default | K7: Put the supplier bill inside Paytm + Soundbox reminder so Paytm becomes the default place to pay | L7: Dono kaam PhonePe se ho jate hain toh Paytm kyu rakhu. | M7: In-depth (15+ min) | N7: Owner | O7: PhonePe Smartspeaker / QR | P7: Owner's personal phone | Q7: 80000 | R7: Distributor / wholesaler (stock) | S7: 30 | T7: 2000 | U7: PhonePe | V7: Daily perishables (milk, bread, veg) | W7: 4 | X7: 5000 | Y7: Google Pay | AD7: Habit: other app is default | AE7: No | AF7: 3 | AG7: Maybe | AH7: No | AI7: 80000 | AJ7: 0 | AK7: 0 | AL7: 0
A8: VOC-005 | B8: 46289 | C8: Merchant | D8: Kalyanpur | E8: General / FMCG store | F8: Google Pay for stock bills; PhonePe for rent | G8: Google Pay | H8: Paytm me feature hai kya supplier ko dene ka? Pata nahi tha. | I8: Customers pay on Paytm Soundbox; receiving only, no supplier payment goes through Paytm. Did not know Paytm can pay suppliers. | J8: Unaware of feature | K8: Awareness at the counter: Soundbox / app prompt that Paytm can pay suppliers; keen on pay-later | L8: Paytm me feature hai kya supplier ko dene ka? Pata nahi tha. | M8: In-depth (15+ min) | O8: Paytm Soundbox | P8: Shop phone | Q8: 250000 | R8: Distributor / wholesaler (stock) | S8: 5 | T8: 30000 | U8: Google Pay | V8: Shop rent | W8: 1 | X8: 20000 | Y8: PhonePe | AD8: Didn't know Paytm can pay suppliers | AE8: No | AF8: 5 | AG8: Yes | AH8: Not yet | AI8: 170000 | AJ8: 0 | AK8: 0 | AL8: 1
A9: VOC-006 | B9: 46289 | C9: Merchant | D9: MT Section | E9: Mobile / electronics | F9: Bank transfer (NEFT/RTGS) for stock bills; Cash for staff salary | G9: None (NEFT / cash only) | H9: Distributor direct account me transfer mangta hai NEFT se bade amount ke liye. | I9: Customers pay on Google Pay QR; Paytm not used for receiving or paying suppliers. Knew Paytm can pay suppliers but still uses other apps. | J9: High ticket sizes prefer NEFT | K9: Pay supplier's bank account over UPI (bills are under ₹1 L) with invoice attached; keen on pay-later | L9: Distributor direct account me transfer mangta hai NEFT se bade amount ke liye. | M9: In-depth (15+ min) | N9: Owner | O9: Google Pay QR | P9: Owner's personal phone | Q9: 400000 | R9: Distributor / wholesaler (stock) | S9: 3 | T9: 80000 | U9: Bank transfer (NEFT/RTGS) | V9: Staff salary | W9: 1 | X9: 15000 | Y9: Cash | AD9: Big bills go by NEFT / RTGS | AE9: Yes | AF9: 4 | AG9: Yes | AH9: Yes | AI9: 0 | AJ9: 0 | AL9: 0
A10: VOC-007 | B10: 46289 | C10: Merchant | D10: Hall 5 Canteen | E10: Restaurant / dhaba / canteen | F10: Cash for daily perishables; PhonePe for stock bills | G10: PhonePe | I10: Customers pay on Paytm Soundbox; receiving only, no supplier payment goes through Paytm. Did not know Paytm can pay suppliers. | J10: Staff manages cash drawer | K10: Give staff a controlled way to pay suppliers from the shop's Paytm, with a nightly summary for the owner | L10: Raat ko hisaab karna padta hai, ladka cash ginta hai. | M10: In-depth (15+ min) | O10: Paytm Soundbox | P10: Staff pays | Q10: 200000 | R10: Daily perishables (milk, bread, veg) | S10: 30 | T10: 3000 | U10: Cash | V10: Distributor / wholesaler (stock) | W10: 4 | X10: 25000 | Y10: PhonePe | AD10: Other | AE10: No | AF10: 4 | AG10: Maybe | AH10: Yes | AI10: 100000 | AJ10: 0 | AK10: 0 | AL10: 1
A11: VOC-008 | B11: 46289 | C11: Merchant | D11: Kakadeo | E11: Stationery / books | F11: Google Pay for stock bills; PhonePe for rent | G11: Google Pay | H11: Aadat ban gayi hai GPay ki pichle teen saal se. | I11: Customers pay on Paytm Soundbox; receiving only, no supplier payment goes through Paytm. Did not know Paytm can pay suppliers. | J11: Habit: other app is default | K11: Put the supplier bill inside Paytm + Soundbox reminder so Paytm becomes the default place to pay; keen on pay-later | L11: Aadat ban gayi hai GPay ki pichle teen saal se. | M11: In-depth (15+ min) | N11: Owner | O11: Paytm Soundbox | P11: Owner's personal phone | Q11: 100000 | R11: Distributor / wholesaler (stock) | S11: 2 | T11: 40000 | U11: Google Pay | V11: Shop rent | W11: 1 | X11: 12000 | Y11: PhonePe | AD11: Habit: other app is default | AE11: No | AF11: 5 | AG11: Yes | AH11: No | AI11: 92000 | AJ11: 0 | AK11: 0 | AL11: 1
A12: VOC-009 | B12: 46289 | C12: Merchant | D12: Kalyanpur | E12: Hardware / paint / sanitary | F12: Bank transfer (NEFT/RTGS) for stock bills; PhonePe for stock bills | G12: PhonePe | H12: GST bill hota hai toh bank se karte hain, baki salesman aake QR deta hai. | I12: Customers pay on Bank / other QR; Paytm not used for receiving or paying suppliers. Knew Paytm can pay suppliers but still uses other apps. | J12: Salesman shows his own QR | K12: Distributor-led onboarding: supplier's bill/QR lands in Chukta, salesman asks shop to pay there | L12: GST bill hota hai toh bank se karte hain, baki salesman aake QR deta hai. | M12: In-depth (15+ min) | N12: Owner | O12: Bank / other QR | P12: Owner's personal phone | Q12: 350000 | R12: Distributor / wholesaler (stock) | S12: 4 | T12: 50000 | U12: Bank transfer (NEFT/RTGS) | V12: Distributor / wholesaler (stock) | W12: 2 | X12: 75000 | Y12: PhonePe | AD12: Supplier shared another app's QR / asked | AE12: Yes | AF12: 3 | AG12: Maybe | AH12: Yes | AI12: 150000 | AJ12: 0 | AK12: 0 | AL12: 0
A13: VOC-010 | B13: 46289 | C13: Merchant | D13: IITK Shopping Complex | E13: Clothing / footwear | F13: PhonePe for stock bills; Cash for staff salary | G13: PhonePe | I13: Customers pay on Paytm Soundbox; receiving only, no supplier payment goes through Paytm. Did not know Paytm can pay suppliers. | J13: App segregation | K13: Make paying as easy as receiving inside Paytm for Business, on the same phone; keen on pay-later | L13: Dukaan ke phone me bas Soundbox hai, payment mere private phone se hoti hai. | M13: In-depth (15+ min) | N13: Owner | O13: Paytm Soundbox | P13: Owner's personal phone | Q13: 200000 | R13: Distributor / wholesaler (stock) | S13: 2 | T13: 60000 | U13: PhonePe | V13: Staff salary | W13: 1 | X13: 10000 | Y13: Cash | AD13: Pays from personal phone (Paytm Business is only for receiving) | AE13: No | AF13: 5 | AG13: Yes | AH13: Not yet | AI13: 120000 | AJ13: 0 | AK13: 0 | AL13: 1
A14: VOC-011 | B14: 46289 | C14: Merchant | D14: Nankari | E14: Kirana / grocery | F14: PhonePe for stock bills; Google Pay for daily perishables | G14: PhonePe | H14: PhonePe hi chalta hai, salesman wahi QR deta hai. | I14: Customers pay on Paytm QR only; receiving only, no supplier payment goes through Paytm. Did not know Paytm can pay suppliers. | J14: Salesman shows his own QR | K14: Distributor-led onboarding: supplier's bill/QR lands in Chukta, salesman asks shop to pay there | L14: PhonePe hi chalta hai, salesman wahi QR deta hai. | M14: Short (5 min) | N14: Owner | O14: Paytm QR only | P14: Owner's personal phone | Q14: 150000 | R14: Distributor / wholesaler (stock) | S14: 6 | T14: 15000 | U14: PhonePe | V14: Daily perishables (milk, bread, veg) | W14: 30 | X14: 800 | Y14: Google Pay | AD14: Supplier shared another app's QR / asked | AE14: No | AF14: 4 | AG14: Maybe | AH14: No | AI14: 114000 | AJ14: 0 | AK14: 0 | AL14: 1
A15: VOC-012 | B15: 46289 | C15: Merchant | D15: Hall 2 Canteen | E15: Restaurant / dhaba / canteen | F15: Cash for daily perishables; PhonePe for stock bills | G15: PhonePe | I15: Customers pay on Paytm Soundbox; receiving only, no supplier payment goes through Paytm. Did not know Paytm can pay suppliers. | J15: Short on cash when stock arrives | K15: 7-day pay-later at stock time; supplier still paid instantly | L15: Cash nikalna padta hai ATM se sabji wale ke liye. | M15: Short (5 min) | O15: Paytm Soundbox | P15: Mostly cash / cheque | Q15: 120000 | R15: Daily perishables (milk, bread, veg) | S15: 30 | T15: 2500 | U15: Cash | V15: Distributor / wholesaler (stock) | W15: 4 | X15: 10000 | Y15: PhonePe | AD15: Short on cash when stock arrives | AE15: No | AF15: 5 | AG15: Yes | AH15: Yes | AI15: 40000 | AJ15: 0 | AK15: 0 | AL15: 1
A16: VOC-013 | B16: 46289 | C16: Merchant | D16: Kalyanpur | E16: Pharmacy / chemist | F16: Google Pay for stock bills; Cash for staff salary | G16: Google Pay | H16: Scan karke pay karne me GPay aage hai. | I16: Customers pay on Google Pay QR; Paytm not used for receiving or paying suppliers. Did not know Paytm can pay suppliers. | J16: Habit: other app is default | K16: Put the supplier bill inside Paytm + Soundbox reminder so Paytm becomes the default place to pay; keen on pay-later | L16: Scan karke pay karne me GPay aage hai. | M16: Short (5 min) | N16: Owner | O16: Google Pay QR | P16: Owner's personal phone | Q16: 400000 | R16: Distributor / wholesaler (stock) | S16: 10 | T16: 30000 | U16: Google Pay | V16: Staff salary | W16: 1 | X16: 14000 | Y16: Cash | AD16: Habit: other app is default | AE16: No | AF16: 4 | AG16: Yes | AH16: Not yet | AI16: 300000 | AJ16: 0 | AK16: 0 | AL16: 0
A17: VOC-014 | B17: 46289 | C17: Merchant | D17: Gurdev Palace | E17: General / FMCG store | F17: PhonePe for stock bills; Bank transfer (NEFT/RTGS) for rent | G17: PhonePe | H17: Hisaab alag alag jagah faila hua hai, PhonePe par history aasan hai. | I17: Customers pay on Paytm Soundbox; receiving only, no supplier payment goes through Paytm. Knew Paytm can pay suppliers but still uses other apps. | J17: Ledger reconciliation | K17: Invoice-tagged payments + auto purchase register; keen on pay-later | L17: Hisaab alag alag jagah faila hua hai, PhonePe par history aasan hai. | M17: Short (5 min) | N17: Owner | O17: Paytm Soundbox | P17: Owner's personal phone | Q17: 180000 | R17: Distributor / wholesaler (stock) | S17: 5 | T17: 25000 | U17: PhonePe | V17: Shop rent | W17: 1 | X17: 15000 | Y17: Bank transfer (NEFT/RTGS) | AD17: Hard to track which bill is paid | AE17: Yes | AF17: 5 | AG17: Yes | AH17: No | AI17: 125000 | AJ17: 0 | AK17: 0 | AL17: 1
A18: VOC-015 | B18: 46289 | C18: Merchant | D18: Hall 12 Canteen | E18: Restaurant / dhaba / canteen | F18: PhonePe for daily perishables; Google Pay for stock bills | G18: PhonePe | H18: Ek hi app me sab ho jaye toh badhiya hai. | I18: Customers pay on Paytm QR only; receiving only, no supplier payment goes through Paytm. Did not know Paytm can pay suppliers. | J18: Habit: other app is default | K18: Put the supplier bill inside Paytm + Soundbox reminder so Paytm becomes the default place to pay | L18: Ek hi app me sab ho jaye toh badhiya hai. | M18: Short (5 min) | O18: Paytm QR only | P18: Shop phone | Q18: 90000 | R18: Daily perishables (milk, bread, veg) | S18: 30 | T18: 1500 | U18: PhonePe | V18: Distributor / wholesaler (stock) | W18: 2 | X18: 20000 | Y18: Google Pay | AD18: Habit: other app is default | AE18: No | AF18: 4 | AG18: Maybe | AH18: Not yet | AI18: 85000 | AJ18: 0 | AK18: 0 | AL18: 1
A19: VOC-016 | B19: 46289 | C19: Merchant | D19: Kakadeo | E19: Kirana / grocery | F19: PhonePe for stock bills; Cash for rent | G19: PhonePe | H19: GPay par salesman ka QR scanned rehta hai, wahi use karta hu. | I19: Customers pay on Paytm Soundbox; receiving only, no supplier payment goes through Paytm. Did not know Paytm can pay suppliers. | J19: Salesman shows his own QR | K19: Distributor-led onboarding: supplier's bill/QR lands in Chukta, salesman asks shop to pay there; keen on pay-later | L19: GPay par salesman ka QR scanned rehta hai, wahi use karta hu. | M19: Short (5 min) | N19: Owner | O19: Paytm Soundbox | P19: Owner's personal phone | Q19: 220000 | R19: Distributor / wholesaler (stock) | S19: 8 | T19: 20000 | U19: PhonePe | V19: Shop rent | W19: 1 | X19: 18000 | Y19: Cash | AD19: Supplier shared another app's QR / asked | AE19: No | AF19: 5 | AG19: Yes | AH19: Yes | AI19: 160000 | AJ19: 0 | AK19: 0 | AL19: 1
A20: VOC-017 | B20: 46289 | C20: Merchant | D20: Nankari | E20: Dairy / bakery / sweets | F20: Cash for stock bills; PhonePe for rent | G20: PhonePe | H20: Doodh wala cash ya PhonePe mangta hai daily. | I20: Customers pay on PhonePe Smartspeaker / QR; Paytm not used for receiving or paying suppliers. Did not know Paytm can pay suppliers. | J20: Habit: other app is default | K20: Put the supplier bill inside Paytm + Soundbox reminder so Paytm becomes the default place to pay | L20: Doodh wala cash ya PhonePe mangta hai daily. | M20: Short (5 min) | O20: PhonePe Smartspeaker / QR | P20: Staff pays | Q20: 70000 | R20: Distributor / wholesaler (stock) | S20: 30 | T20: 1500 | U20: Cash | V20: Shop rent | W20: 1 | X20: 10000 | Y20: PhonePe | AD20: Habit: other app is default | AE20: No | AF20: 3 | AG20: No | AH20: Yes | AI20: 10000 | AJ20: 0 | AK20: 0 | AL20: 0
A21: VOC-018 | B21: 46289 | C21: Merchant | D21: IITK Shopping Complex | E21: Stationery / books | F21: Google Pay for stock bills; Cash for staff salary | G21: Google Pay | H21: Paytm business app kholna bhari lagta hai payment ke liye. | I21: Customers pay on Paytm Soundbox; receiving only, no supplier payment goes through Paytm. Did not know Paytm can pay suppliers. | J21: App segregation | K21: Make paying as easy as receiving inside Paytm for Business, on the same phone; keen on pay-later | L21: Paytm business app kholna bhari lagta hai payment ke liye. | M21: Short (5 min) | N21: Owner | O21: Paytm Soundbox | P21: Owner's personal phone | Q21: 80000 | R21: Distributor / wholesaler (stock) | S21: 2 | T21: 30000 | U21: Google Pay | V21: Staff salary | W21: 1 | X21: 8000 | Y21: Cash | AD21: Pays from personal phone (Paytm Business is only for receiving) | AE21: No | AF21: 4 | AG21: Yes | AH21: No | AI21: 60000 | AJ21: 0 | AK21: 0 | AL21: 1
A22: VOC-019 | B22: 46289 | C22: Merchant | D22: Bithoor Road | E22: Hardware / paint / sanitary | F22: Bank transfer (NEFT/RTGS) for stock bills; PhonePe for stock bills | G22: PhonePe | H22: Bade payment bank transfer se hi safe lagte hain. | I22: Customers pay on Paytm QR only; receiving only, no supplier payment goes through Paytm. Knew Paytm can pay suppliers but still uses other apps. | J22: Trust/Large amounts | K22: Pay supplier's bank account over UPI (bills are under ₹1 L) with invoice attached | L22: Bade payment bank transfer se hi safe lagte hain. | M22: Short (5 min) | N22: Owner | O22: Paytm QR only | P22: Owner's personal phone | Q22: 280000 | R22: Distributor / wholesaler (stock) | S22: 4 | T22: 50000 | U22: Bank transfer (NEFT/RTGS) | V22: Distributor / wholesaler (stock) | W22: 4 | X22: 15000 | Y22: PhonePe | AD22: Big bills go by NEFT / RTGS | AE22: Yes | AF22: 3 | AG22: Maybe | AH22: Not yet | AI22: 60000 | AJ22: 0 | AK22: 0 | AL22: 1
A23: VOC-020 | B23: 46289 | C23: Merchant | D23: Kalyanpur | E23: Kirana / grocery | F23: PhonePe for stock bills; Cash for daily perishables | G23: PhonePe | I23: Customers pay on Paytm Soundbox; receiving only, no supplier payment goes through Paytm. Did not know Paytm can pay suppliers. | J23: Short on cash when stock arrives | K23: 7-day pay-later at stock time; supplier still paid instantly | L23: Cash kam padta hai toh udhaar likhte hain copy me. | M23: Short (5 min) | O23: Paytm Soundbox | P23: Mostly cash / cheque | Q23: 180000 | R23: Distributor / wholesaler (stock) | S23: 6 | T23: 15000 | U23: PhonePe | V23: Daily perishables (milk, bread, veg) | W23: 30 | X23: 1000 | Y23: Cash | AD23: Short on cash when stock arrives | AE23: No | AF23: 5 | AG23: Yes | AH23: Yes | AI23: 90000 | AJ23: 0 | AK23: 0 | AL23: 1
A24: VOC-021 | B24: 46289 | C24: Merchant | D24: Hall 13 Canteen | E24: Restaurant / dhaba / canteen | F24: Google Pay for daily perishables; PhonePe for stock bills | G24: Google Pay | H24: Canteen ka hisaab daily GPay se set ho jata hai. | I24: Customers pay on Paytm Soundbox; receiving only, no supplier payment goes through Paytm. Did not know Paytm can pay suppliers. | J24: Habit: other app is default | K24: Put the supplier bill inside Paytm + Soundbox reminder so Paytm becomes the default place to pay | L24: Canteen ka hisaab daily GPay se set ho jata hai. | M24: Short (5 min) | N24: Owner | O24: Paytm Soundbox | P24: Owner's personal phone | Q24: 140000 | R24: Daily perishables (milk, bread, veg) | S24: 30 | T24: 3000 | U24: Google Pay | V24: Distributor / wholesaler (stock) | W24: 2 | X24: 20000 | Y24: PhonePe | AD24: Habit: other app is default | AE24: No | AF24: 4 | AG24: Maybe | AH24: No | AI24: 130000 | AJ24: 0 | AK24: 0 | AL24: 1
A25: VOC-022 | B25: 46289 | C25: Merchant | D25: MT Section | E25: Mobile / electronics | F25: Bank transfer (NEFT/RTGS) for stock bills; PhonePe for rent | G25: PhonePe | H25: Mobile accessories wali agency GPay par cash nahi leti bada, RTGS mangte hain. | I25: Customers pay on Paytm Soundbox; receiving only, no supplier payment goes through Paytm. Did not know Paytm can pay suppliers. | J25: High ticket sizes | K25: Pay supplier's bank account over UPI (bills are under ₹1 L) with invoice attached; keen on pay-later | L25: Mobile accessories wali agency GPay par cash nahi leti bada, RTGS mangte hain. | M25: Short (5 min) | N25: Owner | O25: Paytm Soundbox | P25: Owner's personal phone | Q25: 350000 | R25: Distributor / wholesaler (stock) | S25: 4 | T25: 70000 | U25: Bank transfer (NEFT/RTGS) | V25: Shop rent | W25: 1 | X25: 25000 | Y25: PhonePe | AD25: Big bills go by NEFT / RTGS | AE25: No | AF25: 4 | AG25: Yes | AH25: Yes | AI25: 25000 | AJ25: 0 | AK25: 0 | AL25: 1
A26: VOC-023 | B26: 46289 | C26: Merchant | D26: Kakadeo | E26: Pharmacy / chemist | F26: Google Pay for stock bills; Cash for staff salary | G26: Google Pay | H26: Medical wale GPay prefer karte hain, wahi chalta aa raha hai. | I26: Customers pay on Paytm QR only; receiving only, no supplier payment goes through Paytm. Knew Paytm can pay suppliers but still uses other apps. | J26: Salesman shows his own QR | K26: Distributor-led onboarding: supplier's bill/QR lands in Chukta, salesman asks shop to pay there; keen on pay-later | L26: Medical wale GPay prefer karte hain, wahi chalta aa raha hai. | M26: Short (5 min) | N26: Owner | O26: Paytm QR only | P26: Owner's personal phone | Q26: 450000 | R26: Distributor / wholesaler (stock) | S26: 12 | T26: 30000 | U26: Google Pay | V26: Staff salary | W26: 1 | X26: 15000 | Y26: Cash | AD26: Supplier shared another app's QR / asked | AE26: Yes | AF26: 5 | AG26: Yes | AH26: Not yet | AI26: 360000 | AJ26: 0 | AK26: 0 | AL26: 1
A27: VOC-024 | B27: 46289 | C27: Merchant | D27: Nankari | E27: General / FMCG store | F27: PhonePe for stock bills; Cash for rent | G27: PhonePe | H27: PhonePe sab use karte hain yahan gali me. | I27: Customers pay on PhonePe Smartspeaker / QR; Paytm not used for receiving or paying suppliers. Did not know Paytm can pay suppliers. | J27: Habit: other app is default | K27: Put the supplier bill inside Paytm + Soundbox reminder so Paytm becomes the default place to pay | L27: PhonePe sab use karte hain yahan gali me. | M27: Short (5 min) | N27: Owner | O27: PhonePe Smartspeaker / QR | P27: Owner's personal phone | Q27: 160000 | R27: Distributor / wholesaler (stock) | S27: 5 | T27: 20000 | U27: PhonePe | V27: Shop rent | W27: 1 | X27: 10000 | Y27: Cash | AD27: Habit: other app is default | AE27: No | AF27: 3 | AG27: Maybe | AH27: Yes | AI27: 100000 | AJ27: 0 | AK27: 0 | AL27: 0
A28: VOC-025 | B28: 46289 | C28: Merchant | D28: IITK Shopping Complex | E28: Kirana / grocery | F28: Google Pay for stock bills; Bank transfer (NEFT/RTGS) for rent | G28: Google Pay | H28: Soundbox bolta hai toh trust hota hai, par pay karne ke liye PhonePe theek hai. | I28: Customers pay on Paytm Soundbox; receiving only, no supplier payment goes through Paytm. Did not know Paytm can pay suppliers. | J28: App segregation | K28: Make paying as easy as receiving inside Paytm for Business, on the same phone; keen on pay-later | L28: Soundbox bolta hai toh trust hota hai, par pay karne ke liye PhonePe theek hai. | M28: Short (5 min) | O28: Paytm Soundbox | P28: Shop phone | Q28: 280000 | R28: Distributor / wholesaler (stock) | S28: 8 | T28: 25000 | U28: Google Pay | V28: Shop rent | W28: 1 | X28: 15000 | Y28: Bank transfer (NEFT/RTGS) | AD28: Pays from personal phone (Paytm Business is only for receiving) | AE28: No | AF28: 5 | AG28: Yes | AH28: No | AI28: 200000 | AJ28: 0 | AK28: 0 | AL28: 1
A29: VOC-026 | B29: 46289 | C29: Merchant | D29: Hall 5 Canteen | E29: Restaurant / dhaba / canteen | F29: Cash for daily perishables; PhonePe for daily perishables | G29: PhonePe | I29: Customers pay on Paytm Soundbox; receiving only, no supplier payment goes through Paytm. Did not know Paytm can pay suppliers. | J29: Short on cash when stock arrives | K29: 7-day pay-later at stock time; supplier still paid instantly | L29: Staff pay karta hai kabhi kabhi cash me subah subah. | M29: Short (5 min) | O29: Paytm Soundbox | P29: Staff pays | Q29: 180000 | R29: Daily perishables (milk, bread, veg) | S29: 30 | T29: 4000 | U29: Cash | V29: Daily perishables (milk, bread, veg) | W29: 30 | X29: 1500 | Y29: PhonePe | AD29: Short on cash when stock arrives | AE29: No | AF29: 4 | AG29: Yes | AH29: Yes | AI29: 45000 | AJ29: 0 | AK29: 0 | AL29: 1
A30: VOC-027 | B30: 46289 | C30: Merchant | D30: Kalyanpur | E30: Clothing / footwear | F30: Bank transfer (NEFT/RTGS) for stock bills; PhonePe for rent | G30: PhonePe | H30: Kapde ka stock bada hota hai, RTGS se jata hai. | I30: Customers pay on Paytm Soundbox; receiving only, no supplier payment goes through Paytm. Knew Paytm can pay suppliers but still uses other apps. | J30: High ticket sizes | K30: Pay supplier's bank account over UPI (bills are under ₹1 L) with invoice attached; keen on pay-later | L30: Kapde ka stock bada hota hai, RTGS se jata hai. | M30: Short (5 min) | N30: Owner | O30: Paytm Soundbox | P30: Owner's personal phone | Q30: 250000 | R30: Distributor / wholesaler (stock) | S30: 3 | T30: 60000 | U30: Bank transfer (NEFT/RTGS) | V30: Shop rent | W30: 1 | X30: 20000 | Y30: PhonePe | AD30: Big bills go by NEFT / RTGS | AE30: Yes | AF30: 4 | AG30: Yes | AH30: Not yet | AI30: 20000 | AJ30: 0 | AK30: 0 | AL30: 1
