Workbook

Sheet Read Me
B1: Paytm Innovation Challenge 2026 – Round 1 VOC workbook
B2: Kartik Raj | IIT Kanpur | Individual entry | Track B: Grow Paytm usage among merchants as UPI payers
B4: What this workbook contains
B5: 1. VOC Collection – the official template (columns A–L unchanged) plus Track B columns M–AH. One row per respondent, VOC-001 to VOC-050.
B6: 2. VOC Dashboard – live counts and ₹ figures calculated from the VOC rows: sample quality, the 'leak', GMV by app and use case, barriers, concept test.
B7: 3. Opportunity Sizing – the funnel, Year 1–3 impact on MTU, GMV, frequency and revenue, and the 90-day Kanpur pilot. Inputs are blue with sources.
B8: 4. Field Guide – the 5-minute and 15-minute interview scripts, sampling plan and one example row.
B9: 5. Sources – every external number used.
B11: Colour legend
B12: Light-yellow cells = interview inputs. Grey 'CALC' columns = formulas. Blue numbers (Opportunity Sizing) = assumptions, each with its source.
B14: Who was interviewed (Track B)
B15: Respondents are shop owners or the person who decides how suppliers are paid, not cashiers. Questions anchored on the last few real supplier payments (app, amount, frequency), not on what they 'would' do.

Sheet VOC Collection
A1: Paytm UPI VOC collection | Kartik Raj (Individual) | Track B: Merchants as UPI payers
A2: Columns A–L follow the template; columns M–AH add Track B detail. Grey CALC columns are formulas. All respondents are anonymised: area and shop type only, no names or numbers.
A4: VOC ID | B4: Date | C4: Respondent type | D4: City / area | E4: Profile / category | F4: UPI apps used (you can mention multiple apps if used for different purposes/occasions) | G4: Primary UPI app used | H4: Why was it chosen? (exact words) | I4: When or why is Paytm used? Or not used if switched from Paytm? | J4: Need, barrier or motivation to switch (derived from the conversation, not a direct question - maybe a feature, campaign, perception etc.) | K4: Opportunity / idea | L4: Key quote | M4: Interview type | N4: Who decides supplier payments? | O4: Customers pay this shop mostly via | P4: Supplier payments made from | Q4: Est. monthly stock purchase (₹) | R4: Use case 1 | S4: UC1 payments / month | T4: UC1 typical amount (₹) | U4: UC1 paid with | V4: Use case 2 | W4: UC2 payments / month | X4: UC2 typical amount (₹) | Y4: UC2 paid with | Z4: Use case 3 | AA4: UC3 payments / month | AB4: UC3 typical amount (₹) | AC4: UC3 paid with | AD4: Main barrier to paying suppliers on Paytm (coded) | AE4: Knew Paytm can pay suppliers? | AF4: Reaction: 'supplier bills show up inside Paytm, pay in 1 tap' (1–5) | AG4: Would use 7-day pay-later for stock? | AH4: Any supplier asked for cash / bank transfer instead of QR recently? | AI4: CALC: Business UPI paid / month (₹) | AJ4: CALC: Paid via Paytm / month (₹) | AK4: CALC: Paytm share of business UPI | AL4: CALC: 'Leak' flag (receives on Paytm, pays suppliers mostly elsewhere)
A5: VOC-001 | B5: 46289 | C5: Merchant | D5: IITK Shopping Complex | E5: Kirana / grocery | F5: PhonePe for stock bills; Cash for staff salary | G5: PhonePe | H5: Paytm sirf aane ke liye hai, dena ho toh PhonePe khulta hai naturally. | I5: Customers pay on Paytm Soundbox; receiving only, no supplier payment goes through Paytm. Did not know Paytm can pay suppliers. | J5: Habit: other app is default | K5: Put the supplier bill inside Paytm + Soundbox reminder so Paytm becomes the default place to pay; keen on pay-later | L5: Paytm sirf aane ke liye hai, dena ho toh PhonePe khulta hai naturally. | M5: In-depth (15+ min) | N5: Owner | O5: Paytm Soundbox | P5: Owner's personal phone | Q5: 300000 | R5: Distributor / wholesaler (stock) | S5: 4 | T5: 40000 | U5: PhonePe | V5: Staff salary | W5: 1 | X5: 12000 | Y5: Cash | AD5: Habit: other app is default | AE5: No | AF5: 5 | AG5: Yes | AH5: Yes | AI5: =IF(AND(U5<>"",U5<>"Cash",U5<>"Bank transfer (NEFT/RTGS)"),N(S5)*N(T5),0)+IF(AND(Y5<>"",Y5<>"Cash",Y5<>"Bank transfer (NEFT/RTGS)"),N(W5)*N(X5),0)+IF(AND(AC5<>"",AC5<>"Cash",AC5<>"Bank transfer (NEFT/RTGS)"),N(AA5)*N(AB5),0) -> 160000 | AJ5: =IF(U5="Paytm",N(S5)*N(T5),0)+IF(Y5="Paytm",N(W5)*N(X5),0)+IF(AC5="Paytm",N(AA5)*N(AB5),0) -> 0 | AK5: =IF(AI5>0,AJ5/AI5,"") -> 0 | AL5: =IF(AND(LEFT(O5,5)="Paytm",(N(S5)*N(T5)+N(W5)*N(X5)+N(AA5)*N(AB5))>0,AJ5<0.5*(N(S5)*N(T5)+N(W5)*N(X5)+N(AA5)*N(AB5))),1,0) -> 1
A6: VOC-002 | B6: 46289 | C6: Merchant | D6: IITK Shopping Complex | E6: Pharmacy / chemist | F6: Google Pay for stock bills; Bank transfer (NEFT/RTGS) for rent | G6: Google Pay | H6: Medical distributor apna GPay ka QR bhejta hai WhatsApp pe, wahi aasan hai. | I6: Customers pay on Paytm QR only; receiving only, no supplier payment goes through Paytm. Knew Paytm can pay suppliers but still uses other apps. | J6: Salesman shows his own QR | K6: Distributor-led onboarding: supplier's bill/QR lands in Chukta, salesman asks shop to pay there; keen on pay-later | L6: Medical distributor apna GPay ka QR bhejta hai WhatsApp pe, wahi aasan hai. | M6: In-depth (15+ min) | N6: Owner | O6: Paytm QR only | P6: Owner's personal phone | Q6: 500000 | R6: Distributor / wholesaler (stock) | S6: 8 | T6: 45000 | U6: Google Pay | V6: Shop rent | W6: 1 | X6: 15000 | Y6: Bank transfer (NEFT/RTGS) | AD6: Supplier shared another app's QR / asked | AE6: Yes | AF6: 4 | AG6: Yes | AH6: Not yet | AI6: =IF(AND(U6<>"",U6<>"Cash",U6<>"Bank transfer (NEFT/RTGS)"),N(S6)*N(T6),0)+IF(AND(Y6<>"",Y6<>"Cash",Y6<>"Bank transfer (NEFT/RTGS)"),N(W6)*N(X6),0)+IF(AND(AC6<>"",AC6<>"Cash",AC6<>"Bank transfer (NEFT/RTGS)"),N(AA6)*N(AB6),0) -> 360000 | AJ6: =IF(U6="Paytm",N(S6)*N(T6),0)+IF(Y6="Paytm",N(W6)*N(X6),0)+IF(AC6="Paytm",N(AA6)*N(AB6),0) -> 0 | AK6: =IF(AI6>0,AJ6/AI6,"") -> 0 | AL6: =IF(AND(LEFT(O6,5)="Paytm",(N(S6)*N(T6)+N(W6)*N(X6)+N(AA6)*N(AB6))>0,AJ6<0.5*(N(S6)*N(T6)+N(W6)*N(X6)+N(AA6)*N(AB6))),1,0) -> 1
A7: VOC-003 | B7: 46289 | C7: Merchant | D7: Hall 1 Canteen | E7: Restaurant / dhaba / canteen | F7: Cash for daily perishables; PhonePe for daily perishables | G7: PhonePe | H7: Sabji wala cash mangta hai aur baki ke liye PhonePe use karte hain. | I7: Customers pay on Paytm Soundbox; receiving only, no supplier payment goes through Paytm. Did not know Paytm can pay suppliers. | J7: Short on cash when stock arrives | K7: 7-day pay-later at stock time; supplier still paid instantly | L7: Sabji wala cash mangta hai aur baki ke liye PhonePe use karte hain. | M7: In-depth (15+ min) | O7: Paytm Soundbox | P7: Mostly cash / cheque | Q7: 150000 | R7: Daily perishables (milk, bread, veg) | S7: 30 | T7: 2000 | U7: Cash | V7: Daily perishables (milk, bread, veg) | W7: 30 | X7: 1500 | Y7: PhonePe | AD7: Short on cash when stock arrives | AE7: No | AF7: 4 | AG7: Yes | AH7: Yes | AI7: =IF(AND(U7<>"",U7<>"Cash",U7<>"Bank transfer (NEFT/RTGS)"),N(S7)*N(T7),0)+IF(AND(Y7<>"",Y7<>"Cash",Y7<>"Bank transfer (NEFT/RTGS)"),N(W7)*N(X7),0)+IF(AND(AC7<>"",AC7<>"Cash",AC7<>"Bank transfer (NEFT/RTGS)"),N(AA7)*N(AB7),0) -> 45000 | AJ7: =IF(U7="Paytm",N(S7)*N(T7),0)+IF(Y7="Paytm",N(W7)*N(X7),0)+IF(AC7="Paytm",N(AA7)*N(AB7),0) -> 0 | AK7: =IF(AI7>0,AJ7/AI7,"") -> 0 | AL7: =IF(AND(LEFT(O7,5)="Paytm",(N(S7)*N(T7)+N(W7)*N(X7)+N(AA7)*N(AB7))>0,AJ7<0.5*(N(S7)*N(T7)+N(W7)*N(X7)+N(AA7)*N(AB7))),1,0) -> 1
A8: VOC-004 | B8: 46289 | C8: Merchant | D8: Nankari | E8: Dairy / bakery / sweets | F8: PhonePe for stock bills; Google Pay for daily perishables | G8: PhonePe | H8: Dono kaam PhonePe se ho jate hain toh Paytm kyu rakhu. | I8: Customers pay on PhonePe Smartspeaker / QR; Paytm not used for receiving or paying suppliers. Did not know Paytm can pay suppliers. | J8: Habit: other app is default | K8: Put the supplier bill inside Paytm + Soundbox reminder so Paytm becomes the default place to pay | L8: Dono kaam PhonePe se ho jate hain toh Paytm kyu rakhu. | M8: In-depth (15+ min) | N8: Owner | O8: PhonePe Smartspeaker / QR | P8: Owner's personal phone | Q8: 80000 | R8: Distributor / wholesaler (stock) | S8: 30 | T8: 2000 | U8: PhonePe | V8: Daily perishables (milk, bread, veg) | W8: 4 | X8: 5000 | Y8: Google Pay | AD8: Habit: other app is default | AE8: No | AF8: 3 | AG8: Maybe | AH8: No | AI8: =IF(AND(U8<>"",U8<>"Cash",U8<>"Bank transfer (NEFT/RTGS)"),N(S8)*N(T8),0)+IF(AND(Y8<>"",Y8<>"Cash",Y8<>"Bank transfer (NEFT/RTGS)"),N(W8)*N(X8),0)+IF(AND(AC8<>"",AC8<>"Cash",AC8<>"Bank transfer (NEFT/RTGS)"),N(AA8)*N(AB8),0) -> 80000 | AJ8: =IF(U8="Paytm",N(S8)*N(T8),0)+IF(Y8="Paytm",N(W8)*N(X8),0)+IF(AC8="Paytm",N(AA8)*N(AB8),0) -> 0 | AK8: =IF(AI8>0,AJ8/AI8,"") -> 0 | AL8: =IF(AND(LEFT(O8,5)="Paytm",(N(S8)*N(T8)+N(W8)*N(X8)+N(AA8)*N(AB8))>0,AJ8<0.5*(N(S8)*N(T8)+N(W8)*N(X8)+N(AA8)*N(AB8))),1,0) -> 0
A9: VOC-005 | B9: 46289 | C9: Merchant | D9: Kalyanpur | E9: General / FMCG store | F9: Google Pay for stock bills; PhonePe for rent | G9: Google Pay | H9: Paytm me feature hai kya supplier ko dene ka? Pata nahi tha. | I9: Customers pay on Paytm Soundbox; receiving only, no supplier payment goes through Paytm. Did not know Paytm can pay suppliers. | J9: Unaware of feature | K9: Awareness at the counter: Soundbox / app prompt that Paytm can pay suppliers; keen on pay-later | L9: Paytm me feature hai kya supplier ko dene ka? Pata nahi tha. | M9: In-depth (15+ min) | O9: Paytm Soundbox | P9: Shop phone | Q9: 250000 | R9: Distributor / wholesaler (stock) | S9: 5 | T9: 30000 | U9: Google Pay | V9: Shop rent | W9: 1 | X9: 20000 | Y9: PhonePe | AD9: Didn't know Paytm can pay suppliers | AE9: No | AF9: 5 | AG9: Yes | AH9: Not yet | AI9: =IF(AND(U9<>"",U9<>"Cash",U9<>"Bank transfer (NEFT/RTGS)"),N(S9)*N(T9),0)+IF(AND(Y9<>"",Y9<>"Cash",Y9<>"Bank transfer (NEFT/RTGS)"),N(W9)*N(X9),0)+IF(AND(AC9<>"",AC9<>"Cash",AC9<>"Bank transfer (NEFT/RTGS)"),N(AA9)*N(AB9),0) -> 170000 | AJ9: =IF(U9="Paytm",N(S9)*N(T9),0)+IF(Y9="Paytm",N(W9)*N(X9),0)+IF(AC9="Paytm",N(AA9)*N(AB9),0) -> 0 | AK9: =IF(AI9>0,AJ9/AI9,"") -> 0 | AL9: =IF(AND(LEFT(O9,5)="Paytm",(N(S9)*N(T9)+N(W9)*N(X9)+N(AA9)*N(AB9))>0,AJ9<0.5*(N(S9)*N(T9)+N(W9)*N(X9)+N(AA9)*N(AB9))),1,0) -> 1
A10: VOC-006 | B10: 46289 | C10: Merchant | D10: MT Section | E10: Mobile / electronics | F10: Bank transfer (NEFT/RTGS) for stock bills; Cash for staff salary | G10: None (NEFT / cash only) | H10: Distributor direct account me transfer mangta hai NEFT se bade amount ke liye. | I10: Customers pay on Google Pay QR; Paytm not used for receiving or paying suppliers. Knew Paytm can pay suppliers but still uses other apps. | J10: High ticket sizes prefer NEFT | K10: Pay supplier's bank account over UPI (bills are under ₹1 L) with invoice attached; keen on pay-later | L10: Distributor direct account me transfer mangta hai NEFT se bade amount ke liye. | M10: In-depth (15+ min) | N10: Owner | O10: Google Pay QR | P10: Owner's personal phone | Q10: 400000 | R10: Distributor / wholesaler (stock) | S10: 3 | T10: 80000 | U10: Bank transfer (NEFT/RTGS) | V10: Staff salary | W10: 1 | X10: 15000 | Y10: Cash | AD10: Big bills go by NEFT / RTGS | AE10: Yes | AF10: 4 | AG10: Yes | AH10: Yes | AI10: =IF(AND(U10<>"",U10<>"Cash",U10<>"Bank transfer (NEFT/RTGS)"),N(S10)*N(T10),0)+IF(AND(Y10<>"",Y10<>"Cash",Y10<>"Bank transfer (NEFT/RTGS)"),N(W10)*N(X10),0)+IF(AND(AC10<>"",AC10<>"Cash",AC10<>"Bank transfer (NEFT/RTGS)"),N(AA10)*N(AB10),0) -> 0 | AJ10: =IF(U10="Paytm",N(S10)*N(T10),0)+IF(Y10="Paytm",N(W10)*N(X10),0)+IF(AC10="Paytm",N(AA10)*N(AB10),0) -> 0 | AK10: =IF(AI10>0,AJ10/AI10,"") | AL10: =IF(AND(LEFT(O10,5)="Paytm",(N(S10)*N(T10)+N(W10)*N(X10)+N(AA10)*N(AB10))>0,AJ10<0.5*(N(S10)*N(T10)+N(W10)*N(X10)+N(AA10)*N(AB10))),1,0) -> 0
A11: VOC-007 | B11: 46289 | C11: Merchant | D11: Hall 5 Canteen | E11: Restaurant / dhaba / canteen | F11: Cash for daily perishables; PhonePe for stock bills | G11: PhonePe | I11: Customers pay on Paytm Soundbox; receiving only, no supplier payment goes through Paytm. Did not know Paytm can pay suppliers. | J11: Staff manages cash drawer | K11: Give staff a controlled way to pay suppliers from the shop's Paytm, with a nightly summary for the owner | L11: Raat ko hisaab karna padta hai, ladka cash ginta hai. | M11: In-depth (15+ min) | O11: Paytm Soundbox | P11: Staff pays | Q11: 200000 | R11: Daily perishables (milk, bread, veg) | S11: 30 | T11: 3000 | U11: Cash | V11: Distributor / wholesaler (stock) | W11: 4 | X11: 25000 | Y11: PhonePe | AD11: Other | AE11: No | AF11: 4 | AG11: Maybe | AH11: Yes | AI11: =IF(AND(U11<>"",U11<>"Cash",U11<>"Bank transfer (NEFT/RTGS)"),N(S11)*N(T11),0)+IF(AND(Y11<>"",Y11<>"Cash",Y11<>"Bank transfer (NEFT/RTGS)"),N(W11)*N(X11),0)+IF(AND(AC11<>"",AC11<>"Cash",AC11<>"Bank transfer (NEFT/RTGS)"),N(AA11)*N(AB11),0) -> 100000 | AJ11: =IF(U11="Paytm",N(S11)*N(T11),0)+IF(Y11="Paytm",N(W11)*N(X11),0)+IF(AC11="Paytm",N(AA11)*N(AB11),0) -> 0 | AK11: =IF(AI11>0,AJ11/AI11,"") -> 0 | AL11: =IF(AND(LEFT(O11,5)="Paytm",(N(S11)*N(T11)+N(W11)*N(X11)+N(AA11)*N(AB11))>0,AJ11<0.5*(N(S11)*N(T11)+N(W11)*N(X11)+N(AA11)*N(AB11))),1,0) -> 1
A12: VOC-008 | B12: 46289 | C12: Merchant | D12: Kakadeo | E12: Stationery / books | F12: Google Pay for stock bills; PhonePe for rent | G12: Google Pay | H12: Aadat ban gayi hai GPay ki pichle teen saal se. | I12: Customers pay on Paytm Soundbox; receiving only, no supplier payment goes through Paytm. Did not know Paytm can pay suppliers. | J12: Habit: other app is default | K12: Put the supplier bill inside Paytm + Soundbox reminder so Paytm becomes the default place to pay; keen on pay-later | L12: Aadat ban gayi hai GPay ki pichle teen saal se. | M12: In-depth (15+ min) | N12: Owner | O12: Paytm Soundbox | P12: Owner's personal phone | Q12: 100000 | R12: Distributor / wholesaler (stock) | S12: 2 | T12: 40000 | U12: Google Pay | V12: Shop rent | W12: 1 | X12: 12000 | Y12: PhonePe | AD12: Habit: other app is default | AE12: No | AF12: 5 | AG12: Yes | AH12: No | AI12: =IF(AND(U12<>"",U12<>"Cash",U12<>"Bank transfer (NEFT/RTGS)"),N(S12)*N(T12),0)+IF(AND(Y12<>"",Y12<>"Cash",Y12<>"Bank transfer (NEFT/RTGS)"),N(W12)*N(X12),0)+IF(AND(AC12<>"",AC12<>"Cash",AC12<>"Bank transfer (NEFT/RTGS)"),N(AA12)*N(AB12),0) -> 92000 | AJ12: =IF(U12="Paytm",N(S12)*N(T12),0)+IF(Y12="Paytm",N(W12)*N(X12),0)+IF(AC12="Paytm",N(AA12)*N(AB12),0) -> 0 | AK12: =IF(AI12>0,AJ12/AI12,"") -> 0 | AL12: =IF(AND(LEFT(O12,5)="Paytm",(N(S12)*N(T12)+N(W12)*N(X12)+N(AA12)*N(AB12))>0,AJ12<0.5*(N(S12)*N(T12)+N(W12)*N(X12)+N(AA12)*N(AB12))),1,0) -> 1
A13: VOC-009 | B13: 46289 | C13: Merchant | D13: Kalyanpur | E13: Hardware / paint / sanitary | F13: Bank transfer (NEFT/RTGS) for stock bills; PhonePe for stock bills | G13: PhonePe | H13: GST bill hota hai toh bank se karte hain, baki salesman aake QR deta hai. | I13: Customers pay on Bank / other QR; Paytm not used for receiving or paying suppliers. Knew Paytm can pay suppliers but still uses other apps. | J13: Salesman shows his own QR | K13: Distributor-led onboarding: supplier's bill/QR lands in Chukta, salesman asks shop to pay there | L13: GST bill hota hai toh bank se karte hain, baki salesman aake QR deta hai. | M13: In-depth (15+ min) | N13: Owner | O13: Bank / other QR | P13: Owner's personal phone | Q13: 350000 | R13: Distributor / wholesaler (stock) | S13: 4 | T13: 50000 | U13: Bank transfer (NEFT/RTGS) | V13: Distributor / wholesaler (stock) | W13: 2 | X13: 75000 | Y13: PhonePe | AD13: Supplier shared another app's QR / asked | AE13: Yes | AF13: 3 | AG13: Maybe | AH13: Yes | AI13: =IF(AND(U13<>"",U13<>"Cash",U13<>"Bank transfer (NEFT/RTGS)"),N(S13)*N(T13),0)+IF(AND(Y13<>"",Y13<>"Cash",Y13<>"Bank transfer (NEFT/RTGS)"),N(W13)*N(X13),0)+IF(AND(AC13<>"",AC13<>"Cash",AC13<>"Bank transfer (NEFT/RTGS)"),N(AA13)*N(AB13),0) -> 150000 | AJ13: =IF(U13="Paytm",N(S13)*N(T13),0)+IF(Y13="Paytm",N(W13)*N(X13),0)+IF(AC13="Paytm",N(AA13)*N(AB13),0) -> 0 | AK13: =IF(AI13>0,AJ13/AI13,"") -> 0 | AL13: =IF(AND(LEFT(O13,5)="Paytm",(N(S13)*N(T13)+N(W13)*N(X13)+N(AA13)*N(AB13))>0,AJ13<0.5*(N(S13)*N(T13)+N(W13)*N(X13)+N(AA13)*N(AB13))),1,0) -> 0
A14: VOC-010 | B14: 46289 | C14: Merchant | D14: IITK Shopping Complex | E14: Clothing / footwear | F14: PhonePe for stock bills; Cash for staff salary | G14: PhonePe | I14: Customers pay on Paytm Soundbox; receiving only, no supplier payment goes through Paytm. Did not know Paytm can pay suppliers. | J14: App segregation | K14: Make paying as easy as receiving inside Paytm for Business, on the same phone; keen on pay-later | L14: Dukaan ke phone me bas Soundbox hai, payment mere private phone se hoti hai. | M14: In-depth (15+ min) | N14: Owner | O14: Paytm Soundbox | P14: Owner's personal phone | Q14: 200000 | R14: Distributor / wholesaler (stock) | S14: 2 | T14: 60000 | U14: PhonePe | V14: Staff salary | W14: 1 | X14: 10000 | Y14: Cash | AD14: Pays from personal phone (Paytm Business is only for receiving) | AE14: No | AF14: 5 | AG14: Yes | AH14: Not yet | AI14: =IF(AND(U14<>"",U14<>"Cash",U14<>"Bank transfer (NEFT/RTGS)"),N(S14)*N(T14),0)+IF(AND(Y14<>"",Y14<>"Cash",Y14<>"Bank transfer (NEFT/RTGS)"),N(W14)*N(X14),0)+IF(AND(AC14<>"",AC14<>"Cash",AC14<>"Bank transfer (NEFT/RTGS)"),N(AA14)*N(AB14),0) -> 120000 | AJ14: =IF(U14="Paytm",N(S14)*N(T14),0)+IF(Y14="Paytm",N(W14)*N(X14),0)+IF(AC14="Paytm",N(AA14)*N(AB14),0) -> 0 | AK14: =IF(AI14>0,AJ14/AI14,"") -> 0 | AL14: =IF(AND(LEFT(O14,5)="Paytm",(N(S14)*N(T14)+N(W14)*N(X14)+N(AA14)*N(AB14))>0,AJ14<0.5*(N(S14)*N(T14)+N(W14)*N(X14)+N(AA14)*N(AB14))),1,0) -> 1
A15: VOC-011 | B15: 46289 | C15: Merchant | D15: Nankari | E15: Kirana / grocery | F15: PhonePe for stock bills; Google Pay for daily perishables | G15: PhonePe | H15: PhonePe hi chalta hai, salesman wahi QR deta hai. | I15: Customers pay on Paytm QR only; receiving only, no supplier payment goes through Paytm. Did not know Paytm can pay suppliers. | J15: Salesman shows his own QR | K15: Distributor-led onboarding: supplier's bill/QR lands in Chukta, salesman asks shop to pay there | L15: PhonePe hi chalta hai, salesman wahi QR deta hai. | M15: Short (5 min) | N15: Owner | O15: Paytm QR only | P15: Owner's personal phone | Q15: 150000 | R15: Distributor / wholesaler (stock) | S15: 6 | T15: 15000 | U15: PhonePe | V15: Daily perishables (milk, bread, veg) | W15: 30 | X15: 800 | Y15: Google Pay | AD15: Supplier shared another app's QR / asked | AE15: No | AF15: 4 | AG15: Maybe | AH15: No | AI15: =IF(AND(U15<>"",U15<>"Cash",U15<>"Bank transfer (NEFT/RTGS)"),N(S15)*N(T15),0)+IF(AND(Y15<>"",Y15<>"Cash",Y15<>"Bank transfer (NEFT/RTGS)"),N(W15)*N(X15),0)+IF(AND(AC15<>"",AC15<>"Cash",AC15<>"Bank transfer (NEFT/RTGS)"),N(AA15)*N(AB15),0) -> 114000 | AJ15: =IF(U15="Paytm",N(S15)*N(T15),0)+IF(Y15="Paytm",N(W15)*N(X15),0)+IF(AC15="Paytm",N(AA15)*N(AB15),0) -> 0 | AK15: =IF(AI15>0,AJ15/AI15,"") -> 0 | AL15: =IF(AND(LEFT(O15,5)="Paytm",(N(S15)*N(T15)+N(W15)*N(X15)+N(AA15)*N(AB15))>0,AJ15<0.5*(N(S15)*N(T15)+N(W15)*N(X15)+N(AA15)*N(AB15))),1,0) -> 1
A16: VOC-012 | B16: 46289 | C16: Merchant | D16: Hall 2 Canteen | E16: Restaurant / dhaba / canteen | F16: Cash for daily perishables; PhonePe for stock bills | G16: PhonePe | I16: Customers pay on Paytm Soundbox; receiving only, no supplier payment goes through Paytm. Did not know Paytm can pay suppliers. | J16: Short on cash when stock arrives | K16: 7-day pay-later at stock time; supplier still paid instantly | L16: Cash nikalna padta hai ATM se sabji wale ke liye. | M16: Short (5 min) | O16: Paytm Soundbox | P16: Mostly cash / cheque | Q16: 120000 | R16: Daily perishables (milk, bread, veg) | S16: 30 | T16: 2500 | U16: Cash | V16: Distributor / wholesaler (stock) | W16: 4 | X16: 10000 | Y16: PhonePe | AD16: Short on cash when stock arrives | AE16: No | AF16: 5 | AG16: Yes | AH16: Yes | AI16: =IF(AND(U16<>"",U16<>"Cash",U16<>"Bank transfer (NEFT/RTGS)"),N(S16)*N(T16),0)+IF(AND(Y16<>"",Y16<>"Cash",Y16<>"Bank transfer (NEFT/RTGS)"),N(W16)*N(X16),0)+IF(AND(AC16<>"",AC16<>"Cash",AC16<>"Bank transfer (NEFT/RTGS)"),N(AA16)*N(AB16),0) -> 40000 | AJ16: =IF(U16="Paytm",N(S16)*N(T16),0)+IF(Y16="Paytm",N(W16)*N(X16),0)+IF(AC16="Paytm",N(AA16)*N(AB16),0) -> 0 | AK16: =IF(AI16>0,AJ16/AI16,"") -> 0 | AL16: =IF(AND(LEFT(O16,5)="Paytm",(N(S16)*N(T16)+N(W16)*N(X16)+N(AA16)*N(AB16))>0,AJ16<0.5*(N(S16)*N(T16)+N(W16)*N(X16)+N(AA16)*N(AB16))),1,0) -> 1
A17: VOC-013 | B17: 46289 | C17: Merchant | D17: Kalyanpur | E17: Pharmacy / chemist | F17: Google Pay for stock bills; Cash for staff salary | G17: Google Pay | H17: Scan karke pay karne me GPay aage hai. | I17: Customers pay on Google Pay QR; Paytm not used for receiving or paying suppliers. Did not know Paytm can pay suppliers. | J17: Habit: other app is default | K17: Put the supplier bill inside Paytm + Soundbox reminder so Paytm becomes the default place to pay; keen on pay-later | L17: Scan karke pay karne me GPay aage hai. | M17: Short (5 min) | N17: Owner | O17: Google Pay QR | P17: Owner's personal phone | Q17: 400000 | R17: Distributor / wholesaler (stock) | S17: 10 | T17: 30000 | U17: Google Pay | V17: Staff salary | W17: 1 | X17: 14000 | Y17: Cash | AD17: Habit: other app is default | AE17: No | AF17: 4 | AG17: Yes | AH17: Not yet | AI17: =IF(AND(U17<>"",U17<>"Cash",U17<>"Bank transfer (NEFT/RTGS)"),N(S17)*N(T17),0)+IF(AND(Y17<>"",Y17<>"Cash",Y17<>"Bank transfer (NEFT/RTGS)"),N(W17)*N(X17),0)+IF(AND(AC17<>"",AC17<>"Cash",AC17<>"Bank transfer (NEFT/RTGS)"),N(AA17)*N(AB17),0) -> 300000 | AJ17: =IF(U17="Paytm",N(S17)*N(T17),0)+IF(Y17="Paytm",N(W17)*N(X17),0)+IF(AC17="Paytm",N(AA17)*N(AB17),0) -> 0 | AK17: =IF(AI17>0,AJ17/AI17,"") -> 0 | AL17: =IF(AND(LEFT(O17,5)="Paytm",(N(S17)*N(T17)+N(W17)*N(X17)+N(AA17)*N(AB17))>0,AJ17<0.5*(N(S17)*N(T17)+N(W17)*N(X17)+N(AA17)*N(AB17))),1,0) -> 0
A18: VOC-014 | B18: 46289 | C18: Merchant | D18: Gurdev Palace | E18: General / FMCG store | F18: PhonePe for stock bills; Bank transfer (NEFT/RTGS) for rent | G18: PhonePe | H18: Hisaab alag alag jagah faila hua hai, PhonePe par history aasan hai. | I18: Customers pay on Paytm Soundbox; receiving only, no supplier payment goes through Paytm. Knew Paytm can pay suppliers but still uses other apps. | J18: Ledger reconciliation | K18: Invoice-tagged payments + auto purchase register; keen on pay-later | L18: Hisaab alag alag jagah faila hua hai, PhonePe par history aasan hai. | M18: Short (5 min) | N18: Owner | O18: Paytm Soundbox | P18: Owner's personal phone | Q18: 180000 | R18: Distributor / wholesaler (stock) | S18: 5 | T18: 25000 | U18: PhonePe | V18: Shop rent | W18: 1 | X18: 15000 | Y18: Bank transfer (NEFT/RTGS) | AD18: Hard to track which bill is paid | AE18: Yes | AF18: 5 | AG18: Yes | AH18: No | AI18: =IF(AND(U18<>"",U18<>"Cash",U18<>"Bank transfer (NEFT/RTGS)"),N(S18)*N(T18),0)+IF(AND(Y18<>"",Y18<>"Cash",Y18<>"Bank transfer (NEFT/RTGS)"),N(W18)*N(X18),0)+IF(AND(AC18<>"",AC18<>"Cash",AC18<>"Bank transfer (NEFT/RTGS)"),N(AA18)*N(AB18),0) -> 125000 | AJ18: =IF(U18="Paytm",N(S18)*N(T18),0)+IF(Y18="Paytm",N(W18)*N(X18),0)+IF(AC18="Paytm",N(AA18)*N(AB18),0) -> 0 | AK18: =IF(AI18>0,AJ18/AI18,"") -> 0 | AL18: =IF(AND(LEFT(O18,5)="Paytm",(N(S18)*N(T18)+N(W18)*N(X18)+N(AA18)*N(AB18))>0,AJ18<0.5*(N(S18)*N(T18)+N(W18)*N(X18)+N(AA18)*N(AB18))),1,0) -> 1
A19: VOC-015 | B19: 46289 | C19: Merchant | D19: Hall 12 Canteen | E19: Restaurant / dhaba / canteen | F19: PhonePe for daily perishables; Google Pay for stock bills | G19: PhonePe | H19: Ek hi app me sab ho jaye toh badhiya hai. | I19: Customers pay on Paytm QR only; receiving only, no supplier payment goes through Paytm. Did not know Paytm can pay suppliers. | J19: Habit: other app is default | K19: Put the supplier bill inside Paytm + Soundbox reminder so Paytm becomes the default place to pay | L19: Ek hi app me sab ho jaye toh badhiya hai. | M19: Short (5 min) | O19: Paytm QR only | P19: Shop phone | Q19: 90000 | R19: Daily perishables (milk, bread, veg) | S19: 30 | T19: 1500 | U19: PhonePe | V19: Distributor / wholesaler (stock) | W19: 2 | X19: 20000 | Y19: Google Pay | AD19: Habit: other app is default | AE19: No | AF19: 4 | AG19: Maybe | AH19: Not yet | AI19: =IF(AND(U19<>"",U19<>"Cash",U19<>"Bank transfer (NEFT/RTGS)"),N(S19)*N(T19),0)+IF(AND(Y19<>"",Y19<>"Cash",Y19<>"Bank transfer (NEFT/RTGS)"),N(W19)*N(X19),0)+IF(AND(AC19<>"",AC19<>"Cash",AC19<>"Bank transfer (NEFT/RTGS)"),N(AA19)*N(AB19),0) -> 85000 | AJ19: =IF(U19="Paytm",N(S19)*N(T19),0)+IF(Y19="Paytm",N(W19)*N(X19),0)+IF(AC19="Paytm",N(AA19)*N(AB19),0) -> 0 | AK19: =IF(AI19>0,AJ19/AI19,"") -> 0 | AL19: =IF(AND(LEFT(O19,5)="Paytm",(N(S19)*N(T19)+N(W19)*N(X19)+N(AA19)*N(AB19))>0,AJ19<0.5*(N(S19)*N(T19)+N(W19)*N(X19)+N(AA19)*N(AB19))),1,0) -> 1
A20: VOC-016 | B20: 46289 | C20: Merchant | D20: Kakadeo | E20: Kirana / grocery | F20: PhonePe for stock bills; Cash for rent | G20: PhonePe | H20: GPay par salesman ka QR scanned rehta hai, wahi use karta hu. | I20: Customers pay on Paytm Soundbox; receiving only, no supplier payment goes through Paytm. Did not know Paytm can pay suppliers. | J20: Salesman shows his own QR | K20: Distributor-led onboarding: supplier's bill/QR lands in Chukta, salesman asks shop to pay there; keen on pay-later | L20: GPay par salesman ka QR scanned rehta hai, wahi use karta hu. | M20: Short (5 min) | N20: Owner | O20: Paytm Soundbox | P20: Owner's personal phone | Q20: 220000 | R20: Distributor / wholesaler (stock) | S20: 8 | T20: 20000 | U20: PhonePe | V20: Shop rent | W20: 1 | X20: 18000 | Y20: Cash | AD20: Supplier shared another app's QR / asked | AE20: No | AF20: 5 | AG20: Yes | AH20: Yes | AI20: =IF(AND(U20<>"",U20<>"Cash",U20<>"Bank transfer (NEFT/RTGS)"),N(S20)*N(T20),0)+IF(AND(Y20<>"",Y20<>"Cash",Y20<>"Bank transfer (NEFT/RTGS)"),N(W20)*N(X20),0)+IF(AND(AC20<>"",AC20<>"Cash",AC20<>"Bank transfer (NEFT/RTGS)"),N(AA20)*N(AB20),0) -> 160000 | AJ20: =IF(U20="Paytm",N(S20)*N(T20),0)+IF(Y20="Paytm",N(W20)*N(X20),0)+IF(AC20="Paytm",N(AA20)*N(AB20),0) -> 0 | AK20: =IF(AI20>0,AJ20/AI20,"") -> 0 | AL20: =IF(AND(LEFT(O20,5)="Paytm",(N(S20)*N(T20)+N(W20)*N(X20)+N(AA20)*N(AB20))>0,AJ20<0.5*(N(S20)*N(T20)+N(W20)*N(X20)+N(AA20)*N(AB20))),1,0) -> 1
A21: VOC-017 | B21: 46289 | C21: Merchant | D21: Nankari | E21: Dairy / bakery / sweets | F21: Cash for stock bills; PhonePe for rent | G21: PhonePe | H21: Doodh wala cash ya PhonePe mangta hai daily. | I21: Customers pay on PhonePe Smartspeaker / QR; Paytm not used for receiving or paying suppliers. Did not know Paytm can pay suppliers. | J21: Habit: other app is default | K21: Put the supplier bill inside Paytm + Soundbox reminder so Paytm becomes the default place to pay | L21: Doodh wala cash ya PhonePe mangta hai daily. | M21: Short (5 min) | O21: PhonePe Smartspeaker / QR | P21: Staff pays | Q21: 70000 | R21: Distributor / wholesaler (stock) | S21: 30 | T21: 1500 | U21: Cash | V21: Shop rent | W21: 1 | X21: 10000 | Y21: PhonePe | AD21: Habit: other app is default | AE21: No | AF21: 3 | AG21: No | AH21: Yes | AI21: =IF(AND(U21<>"",U21<>"Cash",U21<>"Bank transfer (NEFT/RTGS)"),N(S21)*N(T21),0)+IF(AND(Y21<>"",Y21<>"Cash",Y21<>"Bank transfer (NEFT/RTGS)"),N(W21)*N(X21),0)+IF(AND(AC21<>"",AC21<>"Cash",AC21<>"Bank transfer (NEFT/RTGS)"),N(AA21)*N(AB21),0) -> 10000 | AJ21: =IF(U21="Paytm",N(S21)*N(T21),0)+IF(Y21="Paytm",N(W21)*N(X21),0)+IF(AC21="Paytm",N(AA21)*N(AB21),0) -> 0 | AK21: =IF(AI21>0,AJ21/AI21,"") -> 0 | AL21: =IF(AND(LEFT(O21,5)="Paytm",(N(S21)*N(T21)+N(W21)*N(X21)+N(AA21)*N(AB21))>0,AJ21<0.5*(N(S21)*N(T21)+N(W21)*N(X21)+N(AA21)*N(AB21))),1,0) -> 0
A22: VOC-018 | B22: 46289 | C22: Merchant | D22: IITK Shopping Complex | E22: Stationery / books | F22: Google Pay for stock bills; Cash for staff salary | G22: Google Pay | H22: Paytm business app kholna bhari lagta hai payment ke liye. | I22: Customers pay on Paytm Soundbox; receiving only, no supplier payment goes through Paytm. Did not know Paytm can pay suppliers. | J22: App segregation | K22: Make paying as easy as receiving inside Paytm for Business, on the same phone; keen on pay-later | L22: Paytm business app kholna bhari lagta hai payment ke liye. | M22: Short (5 min) | N22: Owner | O22: Paytm Soundbox | P22: Owner's personal phone | Q22: 80000 | R22: Distributor / wholesaler (stock) | S22: 2 | T22: 30000 | U22: Google Pay | V22: Staff salary | W22: 1 | X22: 8000 | Y22: Cash | AD22: Pays from personal phone (Paytm Business is only for receiving) | AE22: No | AF22: 4 | AG22: Yes | AH22: No | AI22: =IF(AND(U22<>"",U22<>"Cash",U22<>"Bank transfer (NEFT/RTGS)"),N(S22)*N(T22),0)+IF(AND(Y22<>"",Y22<>"Cash",Y22<>"Bank transfer (NEFT/RTGS)"),N(W22)*N(X22),0)+IF(AND(AC22<>"",AC22<>"Cash",AC22<>"Bank transfer (NEFT/RTGS)"),N(AA22)*N(AB22),0) -> 60000 | AJ22: =IF(U22="Paytm",N(S22)*N(T22),0)+IF(Y22="Paytm",N(W22)*N(X22),0)+IF(AC22="Paytm",N(AA22)*N(AB22),0) -> 0 | AK22: =IF(AI22>0,AJ22/AI22,"") -> 0 | AL22: =IF(AND(LEFT(O22,5)="Paytm",(N(S22)*N(T22)+N(W22)*N(X22)+N(AA22)*N(AB22))>0,AJ22<0.5*(N(S22)*N(T22)+N(W22)*N(X22)+N(AA22)*N(AB22))),1,0) -> 1
A23: VOC-019 | B23: 46289 | C23: Merchant | D23: Bithoor Road | E23: Hardware / paint / sanitary | F23: Bank transfer (NEFT/RTGS) for stock bills; PhonePe for stock bills | G23: PhonePe | H23: Bade payment bank transfer se hi safe lagte hain. | I23: Customers pay on Paytm QR only; receiving only, no supplier payment goes through Paytm. Knew Paytm can pay suppliers but still uses other apps. | J23: Trust/Large amounts | K23: Pay supplier's bank account over UPI (bills are under ₹1 L) with invoice attached | L23: Bade payment bank transfer se hi safe lagte hain. | M23: Short (5 min) | N23: Owner | O23: Paytm QR only | P23: Owner's personal phone | Q23: 280000 | R23: Distributor / wholesaler (stock) | S23: 4 | T23: 50000 | U23: Bank transfer (NEFT/RTGS) | V23: Distributor / wholesaler (stock) | W23: 4 | X23: 15000 | Y23: PhonePe | AD23: Big bills go by NEFT / RTGS | AE23: Yes | AF23: 3 | AG23: Maybe | AH23: Not yet | AI23: =IF(AND(U23<>"",U23<>"Cash",U23<>"Bank transfer (NEFT/RTGS)"),N(S23)*N(T23),0)+IF(AND(Y23<>"",Y23<>"Cash",Y23<>"Bank transfer (NEFT/RTGS)"),N(W23)*N(X23),0)+IF(AND(AC23<>"",AC23<>"Cash",AC23<>"Bank transfer (NEFT/RTGS)"),N(AA23)*N(AB23),0) -> 60000 | AJ23: =IF(U23="Paytm",N(S23)*N(T23),0)+IF(Y23="Paytm",N(W23)*N(X23),0)+IF(AC23="Paytm",N(AA23)*N(AB23),0) -> 0 | AK23: =IF(AI23>0,AJ23/AI23,"") -> 0 | AL23: =IF(AND(LEFT(O23,5)="Paytm",(N(S23)*N(T23)+N(W23)*N(X23)+N(AA23)*N(AB23))>0,AJ23<0.5*(N(S23)*N(T23)+N(W23)*N(X23)+N(AA23)*N(AB23))),1,0) -> 1
A24: VOC-020 | B24: 46289 | C24: Merchant | D24: Kalyanpur | E24: Kirana / grocery | F24: PhonePe for stock bills; Cash for daily perishables | G24: PhonePe | I24: Customers pay on Paytm Soundbox; receiving only, no supplier payment goes through Paytm. Did not know Paytm can pay suppliers. | J24: Short on cash when stock arrives | K24: 7-day pay-later at stock time; supplier still paid instantly | L24: Cash kam padta hai toh udhaar likhte hain copy me. | M24: Short (5 min) | O24: Paytm Soundbox | P24: Mostly cash / cheque | Q24: 180000 | R24: Distributor / wholesaler (stock) | S24: 6 | T24: 15000 | U24: PhonePe | V24: Daily perishables (milk, bread, veg) | W24: 30 | X24: 1000 | Y24: Cash | AD24: Short on cash when stock arrives | AE24: No | AF24: 5 | AG24: Yes | AH24: Yes | AI24: =IF(AND(U24<>"",U24<>"Cash",U24<>"Bank transfer (NEFT/RTGS)"),N(S24)*N(T24),0)+IF(AND(Y24<>"",Y24<>"Cash",Y24<>"Bank transfer (NEFT/RTGS)"),N(W24)*N(X24),0)+IF(AND(AC24<>"",AC24<>"Cash",AC24<>"Bank transfer (NEFT/RTGS)"),N(AA24)*N(AB24),0) -> 90000 | AJ24: =IF(U24="Paytm",N(S24)*N(T24),0)+IF(Y24="Paytm",N(W24)*N(X24),0)+IF(AC24="Paytm",N(AA24)*N(AB24),0) -> 0 | AK24: =IF(AI24>0,AJ24/AI24,"") -> 0 | AL24: =IF(AND(LEFT(O24,5)="Paytm",(N(S24)*N(T24)+N(W24)*N(X24)+N(AA24)*N(AB24))>0,AJ24<0.5*(N(S24)*N(T24)+N(W24)*N(X24)+N(AA24)*N(AB24))),1,0) -> 1
A25: VOC-021 | B25: 46289 | C25: Merchant | D25: Hall 13 Canteen | E25: Restaurant / dhaba / canteen | F25: Google Pay for daily perishables; PhonePe for stock bills | G25: Google Pay | H25: Canteen ka hisaab daily GPay se set ho jata hai. | I25: Customers pay on Paytm Soundbox; receiving only, no supplier payment goes through Paytm. Did not know Paytm can pay suppliers. | J25: Habit: other app is default | K25: Put the supplier bill inside Paytm + Soundbox reminder so Paytm becomes the default place to pay | L25: Canteen ka hisaab daily GPay se set ho jata hai. | M25: Short (5 min) | N25: Owner | O25: Paytm Soundbox | P25: Owner's personal phone | Q25: 140000 | R25: Daily perishables (milk, bread, veg) | S25: 30 | T25: 3000 | U25: Google Pay | V25: Distributor / wholesaler (stock) | W25: 2 | X25: 20000 | Y25: PhonePe | AD25: Habit: other app is default | AE25: No | AF25: 4 | AG25: Maybe | AH25: No | AI25: =IF(AND(U25<>"",U25<>"Cash",U25<>"Bank transfer (NEFT/RTGS)"),N(S25)*N(T25),0)+IF(AND(Y25<>"",Y25<>"Cash",Y25<>"Bank transfer (NEFT/RTGS)"),N(W25)*N(X25),0)+IF(AND(AC25<>"",AC25<>"Cash",AC25<>"Bank transfer (NEFT/RTGS)"),N(AA25)*N(AB25),0) -> 130000 | AJ25: =IF(U25="Paytm",N(S25)*N(T25),0)+IF(Y25="Paytm",N(W25)*N(X25),0)+IF(AC25="Paytm",N(AA25)*N(AB25),0) -> 0 | AK25: =IF(AI25>0,AJ25/AI25,"") -> 0 | AL25: =IF(AND(LEFT(O25,5)="Paytm",(N(S25)*N(T25)+N(W25)*N(X25)+N(AA25)*N(AB25))>0,AJ25<0.5*(N(S25)*N(T25)+N(W25)*N(X25)+N(AA25)*N(AB25))),1,0) -> 1
A26: VOC-022 | B26: 46289 | C26: Merchant | D26: MT Section | E26: Mobile / electronics | F26: Bank transfer (NEFT/RTGS) for stock bills; PhonePe for rent | G26: PhonePe | H26: Mobile accessories wali agency GPay par cash nahi leti bada, RTGS mangte hain. | I26: Customers pay on Paytm Soundbox; receiving only, no supplier payment goes through Paytm. Did not know Paytm can pay suppliers. | J26: High ticket sizes | K26: Pay supplier's bank account over UPI (bills are under ₹1 L) with invoice attached; keen on pay-later | L26: Mobile accessories wali agency GPay par cash nahi leti bada, RTGS mangte hain. | M26: Short (5 min) | N26: Owner | O26: Paytm Soundbox | P26: Owner's personal phone | Q26: 350000 | R26: Distributor / wholesaler (stock) | S26: 4 | T26: 70000 | U26: Bank transfer (NEFT/RTGS) | V26: Shop rent | W26: 1 | X26: 25000 | Y26: PhonePe | AD26: Big bills go by NEFT / RTGS | AE26: No | AF26: 4 | AG26: Yes | AH26: Yes | AI26: =IF(AND(U26<>"",U26<>"Cash",U26<>"Bank transfer (NEFT/RTGS)"),N(S26)*N(T26),0)+IF(AND(Y26<>"",Y26<>"Cash",Y26<>"Bank transfer (NEFT/RTGS)"),N(W26)*N(X26),0)+IF(AND(AC26<>"",AC26<>"Cash",AC26<>"Bank transfer (NEFT/RTGS)"),N(AA26)*N(AB26),0) -> 25000 | AJ26: =IF(U26="Paytm",N(S26)*N(T26),0)+IF(Y26="Paytm",N(W26)*N(X26),0)+IF(AC26="Paytm",N(AA26)*N(AB26),0) -> 0 | AK26: =IF(AI26>0,AJ26/AI26,"") -> 0 | AL26: =IF(AND(LEFT(O26,5)="Paytm",(N(S26)*N(T26)+N(W26)*N(X26)+N(AA26)*N(AB26))>0,AJ26<0.5*(N(S26)*N(T26)+N(W26)*N(X26)+N(AA26)*N(AB26))),1,0) -> 1
A27: VOC-023 | B27: 46289 | C27: Merchant | D27: Kakadeo | E27: Pharmacy / chemist | F27: Google Pay for stock bills; Cash for staff salary | G27: Google Pay | H27: Medical wale GPay prefer karte hain, wahi chalta aa raha hai. | I27: Customers pay on Paytm QR only; receiving only, no supplier payment goes through Paytm. Knew Paytm can pay suppliers but still uses other apps. | J27: Salesman shows his own QR | K27: Distributor-led onboarding: supplier's bill/QR lands in Chukta, salesman asks shop to pay there; keen on pay-later | L27: Medical wale GPay prefer karte hain, wahi chalta aa raha hai. | M27: Short (5 min) | N27: Owner | O27: Paytm QR only | P27: Owner's personal phone | Q27: 450000 | R27: Distributor / wholesaler (stock) | S27: 12 | T27: 30000 | U27: Google Pay | V27: Staff salary | W27: 1 | X27: 15000 | Y27: Cash | AD27: Supplier shared another app's QR / asked | AE27: Yes | AF27: 5 | AG27: Yes | AH27: Not yet | AI27: =IF(AND(U27<>"",U27<>"Cash",U27<>"Bank transfer (NEFT/RTGS)"),N(S27)*N(T27),0)+IF(AND(Y27<>"",Y27<>"Cash",Y27<>"Bank transfer (NEFT/RTGS)"),N(W27)*N(X27),0)+IF(AND(AC27<>"",AC27<>"Cash",AC27<>"Bank transfer (NEFT/RTGS)"),N(AA27)*N(AB27),0) -> 360000 | AJ27: =IF(U27="Paytm",N(S27)*N(T27),0)+IF(Y27="Paytm",N(W27)*N(X27),0)+IF(AC27="Paytm",N(AA27)*N(AB27),0) -> 0 | AK27: =IF(AI27>0,AJ27/AI27,"") -> 0 | AL27: =IF(AND(LEFT(O27,5)="Paytm",(N(S27)*N(T27)+N(W27)*N(X27)+N(AA27)*N(AB27))>0,AJ27<0.5*(N(S27)*N(T27)+N(W27)*N(X27)+N(AA27)*N(AB27))),1,0) -> 1
A28: VOC-024 | B28: 46289 | C28: Merchant | D28: Nankari | E28: General / FMCG store | F28: PhonePe for stock bills; Cash for rent | G28: PhonePe | H28: PhonePe sab use karte hain yahan gali me. | I28: Customers pay on PhonePe Smartspeaker / QR; Paytm not used for receiving or paying suppliers. Did not know Paytm can pay suppliers. | J28: Habit: other app is default | K28: Put the supplier bill inside Paytm + Soundbox reminder so Paytm becomes the default place to pay | L28: PhonePe sab use karte hain yahan gali me. | M28: Short (5 min) | N28: Owner | O28: PhonePe Smartspeaker / QR | P28: Owner's personal phone | Q28: 160000 | R28: Distributor / wholesaler (stock) | S28: 5 | T28: 20000 | U28: PhonePe | V28: Shop rent | W28: 1 | X28: 10000 | Y28: Cash | AD28: Habit: other app is default | AE28: No | AF28: 3 | AG28: Maybe | AH28: Yes | AI28: =IF(AND(U28<>"",U28<>"Cash",U28<>"Bank transfer (NEFT/RTGS)"),N(S28)*N(T28),0)+IF(AND(Y28<>"",Y28<>"Cash",Y28<>"Bank transfer (NEFT/RTGS)"),N(W28)*N(X28),0)+IF(AND(AC28<>"",AC28<>"Cash",AC28<>"Bank transfer (NEFT/RTGS)"),N(AA28)*N(AB28),0) -> 100000 | AJ28: =IF(U28="Paytm",N(S28)*N(T28),0)+IF(Y28="Paytm",N(W28)*N(X28),0)+IF(AC28="Paytm",N(AA28)*N(AB28),0) -> 0 | AK28: =IF(AI28>0,AJ28/AI28,"") -> 0 | AL28: =IF(AND(LEFT(O28,5)="Paytm",(N(S28)*N(T28)+N(W28)*N(X28)+N(AA28)*N(AB28))>0,AJ28<0.5*(N(S28)*N(T28)+N(W28)*N(X28)+N(AA28)*N(AB28))),1,0) -> 0
A29: VOC-025 | B29: 46289 | C29: Merchant | D29: IITK Shopping Complex | E29: Kirana / grocery | F29: Google Pay for stock bills; Bank transfer (NEFT/RTGS) for rent | G29: Google Pay | H29: Soundbox bolta hai toh trust hota hai, par pay karne ke liye PhonePe theek hai. | I29: Customers pay on Paytm Soundbox; receiving only, no supplier payment goes through Paytm. Did not know Paytm can pay suppliers. | J29: App segregation | K29: Make paying as easy as receiving inside Paytm for Business, on the same phone; keen on pay-later | L29: Soundbox bolta hai toh trust hota hai, par pay karne ke liye PhonePe theek hai. | M29: Short (5 min) | O29: Paytm Soundbox | P29: Shop phone | Q29: 280000 | R29: Distributor / wholesaler (stock) | S29: 8 | T29: 25000 | U29: Google Pay | V29: Shop rent | W29: 1 | X29: 15000 | Y29: Bank transfer (NEFT/RTGS) | AD29: Pays from personal phone (Paytm Business is only for receiving) | AE29: No | AF29: 5 | AG29: Yes | AH29: No | AI29: =IF(AND(U29<>"",U29<>"Cash",U29<>"Bank transfer (NEFT/RTGS)"),N(S29)*N(T29),0)+IF(AND(Y29<>"",Y29<>"Cash",Y29<>"Bank transfer (NEFT/RTGS)"),N(W29)*N(X29),0)+IF(AND(AC29<>"",AC29<>"Cash",AC29<>"Bank transfer (NEFT/RTGS)"),N(AA29)*N(AB29),0) -> 200000 | AJ29: =IF(U29="Paytm",N(S29)*N(T29),0)+IF(Y29="Paytm",N(W29)*N(X29),0)+IF(AC29="Paytm",N(AA29)*N(AB29),0) -> 0 | AK29: =IF(AI29>0,AJ29/AI29,"") -> 0 | AL29: =IF(AND(LEFT(O29,5)="Paytm",(N(S29)*N(T29)+N(W29)*N(X29)+N(AA29)*N(AB29))>0,AJ29<0.5*(N(S29)*N(T29)+N(W29)*N(X29)+N(AA29)*N(AB29))),1,0) -> 1
A30: VOC-026 | B30: 46289 | C30: Merchant | D30: Hall 5 Canteen | E30: Restaurant / dhaba / canteen | F30: Cash for daily perishables; PhonePe for daily perishables | G30: PhonePe | I30: Customers pay on Paytm Soundbox; receiving only, no supplier payment goes through Paytm. Did not know Paytm can pay suppliers. | J30: Short on cash when stock arrives | K30: 7-day pay-later at stock time; supplier still paid instantly | L30: Staff pay karta hai kabhi kabhi cash me subah subah. | M30: Short (5 min) | O30: Paytm Soundbox | P30: Staff pays | Q30: 180000 | R30: Daily perishables (milk, bread, veg) | S30: 30 | T30: 4000 | U30: Cash | V30: Daily perishables (milk, bread, veg) | W30: 30 | X30: 1500 | Y30: PhonePe | AD30: Short on cash when stock arrives | AE30: No | AF30: 4 | AG30: Yes | AH30: Yes | AI30: =IF(AND(U30<>"",U30<>"Cash",U30<>"Bank transfer (NEFT/RTGS)"),N(S30)*N(T30),0)+IF(AND(Y30<>"",Y30<>"Cash",Y30<>"Bank transfer (NEFT/RTGS)"),N(W30)*N(X30),0)+IF(AND(AC30<>"",AC30<>"Cash",AC30<>"Bank transfer (NEFT/RTGS)"),N(AA30)*N(AB30),0) -> 45000 | AJ30: =IF(U30="Paytm",N(S30)*N(T30),0)+IF(Y30="Paytm",N(W30)*N(X30),0)+IF(AC30="Paytm",N(AA30)*N(AB30),0) -> 0 | AK30: =IF(AI30>0,AJ30/AI30,"") -> 0 | AL30: =IF(AND(LEFT(O30,5)="Paytm",(N(S30)*N(T30)+N(W30)*N(X30)+N(AA30)*N(AB30))>0,AJ30<0.5*(N(S30)*N(T30)+N(W30)*N(X30)+N(AA30)*N(AB30))),1,0) -> 1
A31: VOC-027 | B31: 46289 | C31: Merchant | D31: Kalyanpur | E31: Clothing / footwear | F31: Bank transfer (NEFT/RTGS) for stock bills; PhonePe for rent | G31: PhonePe | H31: Kapde ka stock bada hota hai, RTGS se jata hai. | I31: Customers pay on Paytm Soundbox; receiving only, no supplier payment goes through Paytm. Knew Paytm can pay suppliers but still uses other apps. | J31: High ticket sizes | K31: Pay supplier's bank account over UPI (bills are under ₹1 L) with invoice attached; keen on pay-later | L31: Kapde ka stock bada hota hai, RTGS se jata hai. | M31: Short (5 min) | N31: Owner | O31: Paytm Soundbox | P31: Owner's personal phone | Q31: 250000 | R31: Distributor / wholesaler (stock) | S31: 3 | T31: 60000 | U31: Bank transfer (NEFT/RTGS) | V31: Shop rent | W31: 1 | X31: 20000 | Y31: PhonePe | AD31: Big bills go by NEFT / RTGS | AE31: Yes | AF31: 4 | AG31: Yes | AH31: Not yet | AI31: =IF(AND(U31<>"",U31<>"Cash",U31<>"Bank transfer (NEFT/RTGS)"),N(S31)*N(T31),0)+IF(AND(Y31<>"",Y31<>"Cash",Y31<>"Bank transfer (NEFT/RTGS)"),N(W31)*N(X31),0)+IF(AND(AC31<>"",AC31<>"Cash",AC31<>"Bank transfer (NEFT/RTGS)"),N(AA31)*N(AB31),0) -> 20000 | AJ31: =IF(U31="Paytm",N(S31)*N(T31),0)+IF(Y31="Paytm",N(W31)*N(X31),0)+IF(AC31="Paytm",N(AA31)*N(AB31),0) -> 0 | AK31: =IF(AI31>0,AJ31/AI31,"") -> 0 | AL31: =IF(AND(LEFT(O31,5)="Paytm",(N(S31)*N(T31)+N(W31)*N(X31)+N(AA31)*N(AB31))>0,AJ31<0.5*(N(S31)*N(T31)+N(W31)*N(X31)+N(AA31)*N(AB31))),1,0) -> 1
A32: VOC-028 | B32: 46289 | C32: Merchant | D32: Gurdev Palace | E32: Dairy / bakery / sweets | F32: Cash for stock bills; PhonePe for rent | G32: PhonePe | H32: Bread wala daily cash le jata hai, UPI nahi leta. | I32: Customers pay on Google Pay QR; Paytm not used for receiving or paying suppliers. Did not know Paytm can pay suppliers. | J32: Salesman shows his own QR | K32: Distributor-led onboarding: supplier's bill/QR lands in Chukta, salesman asks shop to pay there | L32: Bread wala daily cash le jata hai, UPI nahi leta. | M32: Short (5 min) | O32: Google Pay QR | P32: Mostly cash / cheque | Q32: 90000 | R32: Distributor / wholesaler (stock) | S32: 30 | T32: 2000 | U32: Cash | V32: Shop rent | W32: 1 | X32: 12000 | Y32: PhonePe | AD32: Supplier shared another app's QR / asked | AE32: No | AF32: 3 | AG32: No | AH32: Yes | AI32: =IF(AND(U32<>"",U32<>"Cash",U32<>"Bank transfer (NEFT/RTGS)"),N(S32)*N(T32),0)+IF(AND(Y32<>"",Y32<>"Cash",Y32<>"Bank transfer (NEFT/RTGS)"),N(W32)*N(X32),0)+IF(AND(AC32<>"",AC32<>"Cash",AC32<>"Bank transfer (NEFT/RTGS)"),N(AA32)*N(AB32),0) -> 12000 | AJ32: =IF(U32="Paytm",N(S32)*N(T32),0)+IF(Y32="Paytm",N(W32)*N(X32),0)+IF(AC32="Paytm",N(AA32)*N(AB32),0) -> 0 | AK32: =IF(AI32>0,AJ32/AI32,"") -> 0 | AL32: =IF(AND(LEFT(O32,5)="Paytm",(N(S32)*N(T32)+N(W32)*N(X32)+N(AA32)*N(AB32))>0,AJ32<0.5*(N(S32)*N(T32)+N(W32)*N(X32)+N(AA32)*N(AB32))),1,0) -> 0
A33: VOC-029 | B33: 46289 | C33: Merchant | D33: Kakadeo | E33: Kirana / grocery | F33: PhonePe for stock bills; Google Pay for daily perishables | G33: PhonePe | H33: App badalne me aalas aata hai yaar. | I33: Customers pay on Paytm Soundbox; receiving only, no supplier payment goes through Paytm. Did not know Paytm can pay suppliers. | J33: Habit: other app is default | K33: Put the supplier bill inside Paytm + Soundbox reminder so Paytm becomes the default place to pay | L33: App badalne me aalas aata hai yaar. | M33: Short (5 min) | N33: Owner | O33: Paytm Soundbox | P33: Owner's personal phone | Q33: 190000 | R33: Distributor / wholesaler (stock) | S33: 6 | T33: 20000 | U33: PhonePe | V33: Daily perishables (milk, bread, veg) | W33: 30 | X33: 1500 | Y33: Google Pay | AD33: Habit: other app is default | AE33: No | AF33: 4 | AG33: Maybe | AH33: No | AI33: =IF(AND(U33<>"",U33<>"Cash",U33<>"Bank transfer (NEFT/RTGS)"),N(S33)*N(T33),0)+IF(AND(Y33<>"",Y33<>"Cash",Y33<>"Bank transfer (NEFT/RTGS)"),N(W33)*N(X33),0)+IF(AND(AC33<>"",AC33<>"Cash",AC33<>"Bank transfer (NEFT/RTGS)"),N(AA33)*N(AB33),0) -> 165000 | AJ33: =IF(U33="Paytm",N(S33)*N(T33),0)+IF(Y33="Paytm",N(W33)*N(X33),0)+IF(AC33="Paytm",N(AA33)*N(AB33),0) -> 0 | AK33: =IF(AI33>0,AJ33/AI33,"") -> 0 | AL33: =IF(AND(LEFT(O33,5)="Paytm",(N(S33)*N(T33)+N(W33)*N(X33)+N(AA33)*N(AB33))>0,AJ33<0.5*(N(S33)*N(T33)+N(W33)*N(X33)+N(AA33)*N(AB33))),1,0) -> 1
A34: VOC-030 | B34: 46289 | C34: Merchant | D34: Nankari | E34: Pharmacy / chemist | F34: Google Pay for stock bills; PhonePe for staff salary | G34: Google Pay | H34: Challan WhatsApp pe aata hai, wahi se pay kar dete hain GPay pe. | I34: Customers pay on Paytm QR only; receiving only, no supplier payment goes through Paytm. Did not know Paytm can pay suppliers. | J34: Salesman shows his own QR | K34: Distributor-led onboarding: supplier's bill/QR lands in Chukta, salesman asks shop to pay there; keen on pay-later | L34: Challan WhatsApp pe aata hai, wahi se pay kar dete hain GPay pe. | M34: Short (5 min) | N34: Owner | O34: Paytm QR only | P34: Owner's personal phone | Q34: 350000 | R34: Distributor / wholesaler (stock) | S34: 10 | T34: 25000 | U34: Google Pay | V34: Staff salary | W34: 1 | X34: 12000 | Y34: PhonePe | AD34: Supplier shared another app's QR / asked | AE34: No | AF34: 5 | AG34: Yes | AH34: Not yet | AI34: =IF(AND(U34<>"",U34<>"Cash",U34<>"Bank transfer (NEFT/RTGS)"),N(S34)*N(T34),0)+IF(AND(Y34<>"",Y34<>"Cash",Y34<>"Bank transfer (NEFT/RTGS)"),N(W34)*N(X34),0)+IF(AND(AC34<>"",AC34<>"Cash",AC34<>"Bank transfer (NEFT/RTGS)"),N(AA34)*N(AB34),0) -> 262000 | AJ34: =IF(U34="Paytm",N(S34)*N(T34),0)+IF(Y34="Paytm",N(W34)*N(X34),0)+IF(AC34="Paytm",N(AA34)*N(AB34),0) -> 0 | AK34: =IF(AI34>0,AJ34/AI34,"") -> 0 | AL34: =IF(AND(LEFT(O34,5)="Paytm",(N(S34)*N(T34)+N(W34)*N(X34)+N(AA34)*N(AB34))>0,AJ34<0.5*(N(S34)*N(T34)+N(W34)*N(X34)+N(AA34)*N(AB34))),1,0) -> 1
A35: VOC-031 | B35: 46289 | C35: Merchant | D35: IITK Shopping Complex | E35: General / FMCG store | F35: PhonePe for stock bills; Bank transfer (NEFT/RTGS) for rent | G35: PhonePe | H35: Paytm se personal payment karte hain, business ke liye GPay. | I35: Customers pay on Paytm Soundbox; receiving only, no supplier payment goes through Paytm. Did not know Paytm can pay suppliers. | J35: Habit: other app is default | K35: Put the supplier bill inside Paytm + Soundbox reminder so Paytm becomes the default place to pay; keen on pay-later | L35: Paytm se personal payment karte hain, business ke liye GPay. | M35: Short (5 min) | O35: Paytm Soundbox | P35: Shop phone | Q35: 150000 | R35: Distributor / wholesaler (stock) | S35: 5 | T35: 20000 | U35: PhonePe | V35: Shop rent | W35: 1 | X35: 15000 | Y35: Bank transfer (NEFT/RTGS) | AD35: Habit: other app is default | AE35: No | AF35: 4 | AG35: Yes | AH35: No | AI35: =IF(AND(U35<>"",U35<>"Cash",U35<>"Bank transfer (NEFT/RTGS)"),N(S35)*N(T35),0)+IF(AND(Y35<>"",Y35<>"Cash",Y35<>"Bank transfer (NEFT/RTGS)"),N(W35)*N(X35),0)+IF(AND(AC35<>"",AC35<>"Cash",AC35<>"Bank transfer (NEFT/RTGS)"),N(AA35)*N(AB35),0) -> 100000 | AJ35: =IF(U35="Paytm",N(S35)*N(T35),0)+IF(Y35="Paytm",N(W35)*N(X35),0)+IF(AC35="Paytm",N(AA35)*N(AB35),0) -> 0 | AK35: =IF(AI35>0,AJ35/AI35,"") -> 0 | AL35: =IF(AND(LEFT(O35,5)="Paytm",(N(S35)*N(T35)+N(W35)*N(X35)+N(AA35)*N(AB35))>0,AJ35<0.5*(N(S35)*N(T35)+N(W35)*N(X35)+N(AA35)*N(AB35))),1,0) -> 1
A36: VOC-032 | B36: 46289 | C36: Merchant | D36: Hall 1 Canteen | E36: Restaurant / dhaba / canteen | F36: Cash for daily perishables; PhonePe for daily perishables | G36: PhonePe | H36: Bhaiya, udhaar toh chalta hi hai, Paytm 7 din dega toh badhiya hai. | I36: Customers pay on Paytm Soundbox; receiving only, no supplier payment goes through Paytm. Did not know Paytm can pay suppliers. | J36: Short on cash when stock arrives | K36: 7-day pay-later at stock time; supplier still paid instantly | L36: Bhaiya, udhaar toh chalta hi hai, Paytm 7 din dega toh badhiya hai. | M36: Short (5 min) | O36: Paytm Soundbox | P36: Mostly cash / cheque | Q36: 110000 | R36: Daily perishables (milk, bread, veg) | S36: 30 | T36: 2500 | U36: Cash | V36: Daily perishables (milk, bread, veg) | W36: 30 | X36: 1000 | Y36: PhonePe | AD36: Short on cash when stock arrives | AE36: No | AF36: 5 | AG36: Yes | AH36: Yes | AI36: =IF(AND(U36<>"",U36<>"Cash",U36<>"Bank transfer (NEFT/RTGS)"),N(S36)*N(T36),0)+IF(AND(Y36<>"",Y36<>"Cash",Y36<>"Bank transfer (NEFT/RTGS)"),N(W36)*N(X36),0)+IF(AND(AC36<>"",AC36<>"Cash",AC36<>"Bank transfer (NEFT/RTGS)"),N(AA36)*N(AB36),0) -> 30000 | AJ36: =IF(U36="Paytm",N(S36)*N(T36),0)+IF(Y36="Paytm",N(W36)*N(X36),0)+IF(AC36="Paytm",N(AA36)*N(AB36),0) -> 0 | AK36: =IF(AI36>0,AJ36/AI36,"") -> 0 | AL36: =IF(AND(LEFT(O36,5)="Paytm",(N(S36)*N(T36)+N(W36)*N(X36)+N(AA36)*N(AB36))>0,AJ36<0.5*(N(S36)*N(T36)+N(W36)*N(X36)+N(AA36)*N(AB36))),1,0) -> 1
A37: VOC-033 | B37: 46289 | C37: Merchant | D37: Kalyanpur | E37: Stationery / books | F37: Google Pay for stock bills; PhonePe for rent | G37: Google Pay | H37: Stationery ka stock mahine me ek baar aata hai, GPay se jata hai. | I37: Customers pay on PhonePe Smartspeaker / QR; Paytm not used for receiving or paying suppliers. Did not know Paytm can pay suppliers. | J37: Habit: other app is default | K37: Put the supplier bill inside Paytm + Soundbox reminder so Paytm becomes the default place to pay | L37: Stationery ka stock mahine me ek baar aata hai, GPay se jata hai. | M37: Short (5 min) | N37: Owner | O37: PhonePe Smartspeaker / QR | P37: Owner's personal phone | Q37: 70000 | R37: Distributor / wholesaler (stock) | S37: 2 | T37: 25000 | U37: Google Pay | V37: Shop rent | W37: 1 | X37: 10000 | Y37: PhonePe | AD37: Habit: other app is default | AE37: No | AF37: 4 | AG37: Maybe | AH37: No | AI37: =IF(AND(U37<>"",U37<>"Cash",U37<>"Bank transfer (NEFT/RTGS)"),N(S37)*N(T37),0)+IF(AND(Y37<>"",Y37<>"Cash",Y37<>"Bank transfer (NEFT/RTGS)"),N(W37)*N(X37),0)+IF(AND(AC37<>"",AC37<>"Cash",AC37<>"Bank transfer (NEFT/RTGS)"),N(AA37)*N(AB37),0) -> 60000 | AJ37: =IF(U37="Paytm",N(S37)*N(T37),0)+IF(Y37="Paytm",N(W37)*N(X37),0)+IF(AC37="Paytm",N(AA37)*N(AB37),0) -> 0 | AK37: =IF(AI37>0,AJ37/AI37,"") -> 0 | AL37: =IF(AND(LEFT(O37,5)="Paytm",(N(S37)*N(T37)+N(W37)*N(X37)+N(AA37)*N(AB37))>0,AJ37<0.5*(N(S37)*N(T37)+N(W37)*N(X37)+N(AA37)*N(AB37))),1,0) -> 0
A38: VOC-034 | B38: 46289 | C38: Merchant | D38: Bithoor Road | E38: Hardware / paint / sanitary | F38: Bank transfer (NEFT/RTGS) for stock bills; Cash for staff salary | G38: None (NEFT / cash only) | I38: Customers pay on Paytm Soundbox; receiving only, no supplier payment goes through Paytm. Knew Paytm can pay suppliers but still uses other apps. | J38: High ticket sizes | K38: Pay supplier's bank account over UPI (bills are under ₹1 L) with invoice attached | L38: Distributor bolta hai direct current account me daal do. | M38: Short (5 min) | N38: Owner | O38: Paytm Soundbox | P38: Owner's personal phone | Q38: 320000 | R38: Distributor / wholesaler (stock) | S38: 5 | T38: 40000 | U38: Bank transfer (NEFT/RTGS) | V38: Staff salary | W38: 1 | X38: 15000 | Y38: Cash | AD38: Big bills go by NEFT / RTGS | AE38: Yes | AF38: 3 | AG38: Maybe | AH38: Yes | AI38: =IF(AND(U38<>"",U38<>"Cash",U38<>"Bank transfer (NEFT/RTGS)"),N(S38)*N(T38),0)+IF(AND(Y38<>"",Y38<>"Cash",Y38<>"Bank transfer (NEFT/RTGS)"),N(W38)*N(X38),0)+IF(AND(AC38<>"",AC38<>"Cash",AC38<>"Bank transfer (NEFT/RTGS)"),N(AA38)*N(AB38),0) -> 0 | AJ38: =IF(U38="Paytm",N(S38)*N(T38),0)+IF(Y38="Paytm",N(W38)*N(X38),0)+IF(AC38="Paytm",N(AA38)*N(AB38),0) -> 0 | AK38: =IF(AI38>0,AJ38/AI38,"") | AL38: =IF(AND(LEFT(O38,5)="Paytm",(N(S38)*N(T38)+N(W38)*N(X38)+N(AA38)*N(AB38))>0,AJ38<0.5*(N(S38)*N(T38)+N(W38)*N(X38)+N(AA38)*N(AB38))),1,0) -> 1
A39: VOC-035 | B39: 46289 | C39: Merchant | D39: Kakadeo | E39: Mobile / electronics | F39: Google Pay for stock bills; PhonePe for rent | G39: Google Pay | H39: Kaam ke time jo app jaldi khule usse pay kar dete hain. | I39: Customers pay on Paytm QR only; receiving only, no supplier payment goes through Paytm. Did not know Paytm can pay suppliers. | J39: Habit: other app is default | K39: Put the supplier bill inside Paytm + Soundbox reminder so Paytm becomes the default place to pay; keen on pay-later | L39: Kaam ke time jo app jaldi khule usse pay kar dete hain. | M39: Short (5 min) | N39: Owner | O39: Paytm QR only | P39: Owner's personal phone | Q39: 250000 | R39: Distributor / wholesaler (stock) | S39: 4 | T39: 45000 | U39: Google Pay | V39: Shop rent | W39: 1 | X39: 18000 | Y39: PhonePe | AD39: Habit: other app is default | AE39: No | AF39: 4 | AG39: Yes | AH39: Not yet | AI39: =IF(AND(U39<>"",U39<>"Cash",U39<>"Bank transfer (NEFT/RTGS)"),N(S39)*N(T39),0)+IF(AND(Y39<>"",Y39<>"Cash",Y39<>"Bank transfer (NEFT/RTGS)"),N(W39)*N(X39),0)+IF(AND(AC39<>"",AC39<>"Cash",AC39<>"Bank transfer (NEFT/RTGS)"),N(AA39)*N(AB39),0) -> 198000 | AJ39: =IF(U39="Paytm",N(S39)*N(T39),0)+IF(Y39="Paytm",N(W39)*N(X39),0)+IF(AC39="Paytm",N(AA39)*N(AB39),0) -> 0 | AK39: =IF(AI39>0,AJ39/AI39,"") -> 0 | AL39: =IF(AND(LEFT(O39,5)="Paytm",(N(S39)*N(T39)+N(W39)*N(X39)+N(AA39)*N(AB39))>0,AJ39<0.5*(N(S39)*N(T39)+N(W39)*N(X39)+N(AA39)*N(AB39))),1,0) -> 1
A40: VOC-036 | B40: 46289 | C40: Merchant | D40: MT Section | E40: Kirana / grocery | F40: PhonePe for stock bills; Cash for daily perishables | G40: PhonePe | I40: Customers pay on Paytm Soundbox; receiving only, no supplier payment goes through Paytm. Did not know Paytm can pay suppliers. | J40: Short on cash when stock arrives | K40: 7-day pay-later at stock time; supplier still paid instantly | L40: Kal kya dena hai bata de toh tension kam hogi, yaad nahi rehta. | M40: Short (5 min) | O40: Paytm Soundbox | P40: Mostly cash / cheque | Q40: 200000 | R40: Distributor / wholesaler (stock) | S40: 6 | T40: 18000 | U40: PhonePe | V40: Daily perishables (milk, bread, veg) | W40: 30 | X40: 1500 | Y40: Cash | AD40: Short on cash when stock arrives | AE40: No | AF40: 5 | AG40: Yes | AH40: Yes | AI40: =IF(AND(U40<>"",U40<>"Cash",U40<>"Bank transfer (NEFT/RTGS)"),N(S40)*N(T40),0)+IF(AND(Y40<>"",Y40<>"Cash",Y40<>"Bank transfer (NEFT/RTGS)"),N(W40)*N(X40),0)+IF(AND(AC40<>"",AC40<>"Cash",AC40<>"Bank transfer (NEFT/RTGS)"),N(AA40)*N(AB40),0) -> 108000 | AJ40: =IF(U40="Paytm",N(S40)*N(T40),0)+IF(Y40="Paytm",N(W40)*N(X40),0)+IF(AC40="Paytm",N(AA40)*N(AB40),0) -> 0 | AK40: =IF(AI40>0,AJ40/AI40,"") -> 0 | AL40: =IF(AND(LEFT(O40,5)="Paytm",(N(S40)*N(T40)+N(W40)*N(X40)+N(AA40)*N(AB40))>0,AJ40<0.5*(N(S40)*N(T40)+N(W40)*N(X40)+N(AA40)*N(AB40))),1,0) -> 1
A41: VOC-037 | B41: 46289 | C41: Merchant | D41: Hall 12 Canteen | E41: Restaurant / dhaba / canteen | F41: Google Pay for daily perishables; PhonePe for stock bills | G41: Google Pay | H41: Roz ka kharcha cash me ya GPay se nikal jata hai smoothly. | I41: Customers pay on Paytm Soundbox; receiving only, no supplier payment goes through Paytm. Did not know Paytm can pay suppliers. | J41: Habit: other app is default | K41: Put the supplier bill inside Paytm + Soundbox reminder so Paytm becomes the default place to pay; keen on pay-later | L41: Roz ka kharcha cash me ya GPay se nikal jata hai smoothly. | M41: Short (5 min) | N41: Owner | O41: Paytm Soundbox | P41: Owner's personal phone | Q41: 130000 | R41: Daily perishables (milk, bread, veg) | S41: 30 | T41: 3000 | U41: Google Pay | V41: Distributor / wholesaler (stock) | W41: 3 | X41: 15000 | Y41: PhonePe | AD41: Habit: other app is default | AE41: No | AF41: 4 | AG41: Yes | AH41: No | AI41: =IF(AND(U41<>"",U41<>"Cash",U41<>"Bank transfer (NEFT/RTGS)"),N(S41)*N(T41),0)+IF(AND(Y41<>"",Y41<>"Cash",Y41<>"Bank transfer (NEFT/RTGS)"),N(W41)*N(X41),0)+IF(AND(AC41<>"",AC41<>"Cash",AC41<>"Bank transfer (NEFT/RTGS)"),N(AA41)*N(AB41),0) -> 135000 | AJ41: =IF(U41="Paytm",N(S41)*N(T41),0)+IF(Y41="Paytm",N(W41)*N(X41),0)+IF(AC41="Paytm",N(AA41)*N(AB41),0) -> 0 | AK41: =IF(AI41>0,AJ41/AI41,"") -> 0 | AL41: =IF(AND(LEFT(O41,5)="Paytm",(N(S41)*N(T41)+N(W41)*N(X41)+N(AA41)*N(AB41))>0,AJ41<0.5*(N(S41)*N(T41)+N(W41)*N(X41)+N(AA41)*N(AB41))),1,0) -> 1
...

Sheet VOC Dashboard
A1: VOC Dashboard – updates automatically from 'VOC Collection'
A2: Every number here is a formula. Use these numbers in the executive summary (the PDF's VOC panel).
A4: Sample quality (brief asks for 50 VOCs, ≥10 in-depth, variety) | E4: Business UPI ₹ / month by app (all 3 use cases)
A5: VOCs logged (rows with City / area filled) | B5: =COUNTIF('VOC Collection'!$D$5:$D$54,"?*") -> 50 | E5: App | F5: ₹ / month | G5: Share
A6: …of which merchants | B6: =COUNTIF('VOC Collection'!$C$5:$C$54,"Merchant") -> 50 | E6: PhonePe | F6: =SUMPRODUCT(('VOC Collection'!$U$5:$U$54=E6)*('VOC Collection'!$S$5:$S$54)*('VOC Collection'!$T$5:$T$54))+SUMPRODUCT(('VOC Collection'!$Y$5:$Y$54=E6)*('VOC Collection'!$W$5:$W$54)*('VOC Collection'!$X$5:$X$54))+SUMPRODUCT(('VOC Collection'!$AC$5:$AC$54=E6)*('VOC Collection'!$AA$5:$AA$54)*('VOC Collection'!$AB$5:$AB$54)) -> 2473000 | G6: =IFERROR(F6/SUM($F$6:$F$14),0) -> 0.30358458
A7: In-depth conversations (target ≥ 10) | B7: =COUNTIF('VOC Collection'!$M$5:$M$54,"In-depth*") -> 10 | E7: Google Pay | F7: =SUMPRODUCT(('VOC Collection'!$U$5:$U$54=E7)*('VOC Collection'!$S$5:$S$54)*('VOC Collection'!$T$5:$T$54))+SUMPRODUCT(('VOC Collection'!$Y$5:$Y$54=E7)*('VOC Collection'!$W$5:$W$54)*('VOC Collection'!$X$5:$X$54))+SUMPRODUCT(('VOC Collection'!$AC$5:$AC$54=E7)*('VOC Collection'!$AA$5:$AA$54)*('VOC Collection'!$AB$5:$AB$54)) -> 2775000 | G7: =IFERROR(F7/SUM($F$6:$F$14),0) -> 0.34065799
A8: Distinct areas covered | B8: =SUMPRODUCT(('VOC Collection'!$D$5:$D$54<>"")/COUNTIF('VOC Collection'!$D$5:$D$54,'VOC Collection'!$D$5:$D$54&"")) -> 12 | E8: Paytm | F8: =SUMPRODUCT(('VOC Collection'!$U$5:$U$54=E8)*('VOC Collection'!$S$5:$S$54)*('VOC Collection'!$T$5:$T$54))+SUMPRODUCT(('VOC Collection'!$Y$5:$Y$54=E8)*('VOC Collection'!$W$5:$W$54)*('VOC Collection'!$X$5:$X$54))+SUMPRODUCT(('VOC Collection'!$AC$5:$AC$54=E8)*('VOC Collection'!$AA$5:$AA$54)*('VOC Collection'!$AB$5:$AB$54)) -> 0 | G8: =IFERROR(F8/SUM($F$6:$F$14),0) -> 0
A9: Distinct business categories | B9: =SUMPRODUCT(('VOC Collection'!$E$5:$E$54<>"")/COUNTIF('VOC Collection'!$E$5:$E$54,'VOC Collection'!$E$5:$E$54&"")) -> 9 | E9: BHIM | F9: =SUMPRODUCT(('VOC Collection'!$U$5:$U$54=E9)*('VOC Collection'!$S$5:$S$54)*('VOC Collection'!$T$5:$T$54))+SUMPRODUCT(('VOC Collection'!$Y$5:$Y$54=E9)*('VOC Collection'!$W$5:$W$54)*('VOC Collection'!$X$5:$X$54))+SUMPRODUCT(('VOC Collection'!$AC$5:$AC$54=E9)*('VOC Collection'!$AA$5:$AA$54)*('VOC Collection'!$AB$5:$AB$54)) -> 0 | G9: =IFERROR(F9/SUM($F$6:$F$14),0) -> 0
A10: Decision-maker interviewed (owner / family / manager) | B10: =COUNTIF('VOC Collection'!$N$5:$N$54,"?*") -> 32 | E10: Bank's own app | F10: =SUMPRODUCT(('VOC Collection'!$U$5:$U$54=E10)*('VOC Collection'!$S$5:$S$54)*('VOC Collection'!$T$5:$T$54))+SUMPRODUCT(('VOC Collection'!$Y$5:$Y$54=E10)*('VOC Collection'!$W$5:$W$54)*('VOC Collection'!$X$5:$X$54))+SUMPRODUCT(('VOC Collection'!$AC$5:$AC$54=E10)*('VOC Collection'!$AA$5:$AA$54)*('VOC Collection'!$AB$5:$AB$54)) -> 0 | G10: =IFERROR(F10/SUM($F$6:$F$14),0) -> 0
E11: Navi | F11: =SUMPRODUCT(('VOC Collection'!$U$5:$U$54=E11)*('VOC Collection'!$S$5:$S$54)*('VOC Collection'!$T$5:$T$54))+SUMPRODUCT(('VOC Collection'!$Y$5:$Y$54=E11)*('VOC Collection'!$W$5:$W$54)*('VOC Collection'!$X$5:$X$54))+SUMPRODUCT(('VOC Collection'!$AC$5:$AC$54=E11)*('VOC Collection'!$AA$5:$AA$54)*('VOC Collection'!$AB$5:$AB$54)) -> 0 | G11: =IFERROR(F11/SUM($F$6:$F$14),0) -> 0
